Workbook

Sheet 値リスト
A1: categoryId | G1: processId
A2: ID | B2: 名前 | C2: icon | D2: 説明 | G2: ID | H2: 説明 | I2: 属性 | J2: 効果
A3: flora | B3: 植物 | C3: 🌿 | D3: 葉、花、茎など。調合の基本素材 | G3: grind | H3: すりつぶす | I3: 土属性強化 | J3: 反応性強化
A4: fungi | B4: 菌類 | C4: 🍄 | D4: キノコやカビ。特殊な変化をもたらす | G4: boil | H4: 煮る | I4: 水＋火属性強化 | J4: 融解
A5: liquid | B5: 水質 | C5: 🧪 | D5: 湧き水や朝露。液体ベース素材 | G5: dry | H5: 乾燥させる | I5: 風属性強化 | J5: 強化
A6: mineral | B6: 鉱物 | C6: 🪨 | D6: 石、塩、泥など。無機物素材 | G6: raw | H6: そのまま | I6: 鮮度アップ | J6: 鮮度
A7: creature | B7: 動物性 | C7: 🪶 | D7: 羽根や抜け殻、牙など | G7: ferment | H7: 発酵させる | I7: 無属性化 | J7: 変質
A8: relics | B8: 遺物 | C8: 🏺 | D8: 釘やコイン、ガラス瓶などの人工物 | G8: burn | H8: 焼く | I8: 火属性強化 | J8: 無毒化
A9: processed | B9: 加工品 | C9: 🫙 | D9: 調合の中間素材や二次的素材 | G9: freeze | H9: 凍らせる | I9: 郡属性強化 | J9: 保存
G10: dissolve | H10: 溶かす | I10: 水属性強化 | J10: 融解
G11: distill | H11: 蒸留 | I11: 無属性化 | J11: 純化
A12: effectId（薬効）
A13: ID | B13: 名前 | C13: icon | D13: 説明
A14: healing | B14: 治癒 | C14: 🩹 | D14: 傷口を塞ぎ体力を回復 | G14: timeSlot（例）
A15: detox | B15: 解毒 | C15: 🧪 | D15: 体内の毒素を中和 | G15: ID | H15: 説明
A16: tonic | B16: 滋養強壮 | C16: 🍗 | D16: 肉体の疲れを取り活力を | G16: dawn | H16: 夜明け
A17: stimulation | B17: 興奮 | C17: ⚡ | D17: 集中力・反応速度を一時UP | G17: morning | H17: 朝
A18: sedation | B18: 鎮静 | C18: 💤 | D18: 昂った精神を落ち着かせる | G18: noon | H18: 昼
A19: stable | B19: 安定 | C19: ⚪ | D19: 成分を安定させる | G19: afternoon | H19: 午後
A20: levitation | B20: 浮遊 | C20: 🎈 | D20: 重力の影響を中和する | G20: night | H20: 夜
A21: mystic | B21: 神秘 | C21: ☄️ | D21: 魔力回路を一時的に拡張 | G21: midnight | H21: 深夜
A22: insulation | B22: 防護 | C22: 🛡️ | D22: 属性ダメージを軽減
A23: poison | B23: 猛毒 | C23: 💀 | D23: 生命活動を停止させる | G23: checkType
A24: none | B24: なし | C24: ⚪ | D24: 特筆すべき薬効なし | G24: ID | H24: 説明
A25: reactionId（調合時の効果） | G25: itemId | H25: 特定アイテムID
A26: ID | B26: 表示名 | C26: 説明 | G26: categoryId | H26: カテゴリID
A27: coagulate | B27: 凝固 | C27: 液体や素材を固める。形状を保つのに使う | G27: effectId | H27: 薬効ID
A28: preserve | B28: 保存 | C28: 素材の鮮度や効果を長期間維持する | G28: reactionId | H28: 調合時効果ID
A29: separate | B29: 分離 | C29: 混合物から特定の成分を取り出す | G29: elementId | H29: 属性ID
A30: volatile | B30: 揮発 | C30: 成分を気化させる。気体素材の生成に
A31: permeate | B31: 浸透 | C31: 他の素材や対象に成分を染み込ませる
A32: catalyst | B32: 触媒 | C32: 他の反応を促進する。自身は変化しない
A33: neutralize | B33: 中和 | C33: 酸・毒・属性などの効果を打ち消す
A36: 【色の凡例】
A37: ▼ 日本語で選択入力する列
A38: 🔵 英語IDが自動表示される列（編集不要）

Sheet Terrains
A1: Terrains（地形定義） ― マップの1マスに割り当てられる地形の種類
A2: terrainId | B2: 名前 | C2: 表示色 | D2: 説明
A3: ter_grass | B3: 草むら | C3: #C0DD97 | D3: 丈の低い草が茂る。どこにでもある地形。
A4: ter_shrub | B4: 低木 | C4: #97C459 | D4: 腰までの潅木が茂る。実や葉が採れる。
A5: ter_bare | B5: 裸地 | C5: #D3D1C7 | D5: 草も生えない剥き出しの土。
A6: ter_rock | B6: 岩場 | C6: #B4B2A9 | D6: 大小の岩が転がる。陰に生き物が潜む。
A7: ter_boulder | B7: 大岩 | C7: #888780 | D7: 動かせない巨岩。表面に苔や鉱物。
A8: ter_trunk | B8: 樹幹 | C8: #7A5C3E | D8: 太い木の根元。樹皮を伝う水がある。
A9: ter_leaflitter | B9: 落ち葉だまり | C9: #BA7517 | D9: 積もった落ち葉の下。菌類の温床。
A10: ter_deadwood | B10: 倒木 | C10: #854F0B | D10: 朽ちた倒木。分解者が集まる。
A11: ter_glade | B11: 木漏れ日の空き地 | C11: #EAF3DE | D11: 林の中の明るい隙間。草花が育つ。
A12: ter_river | B12: 川の中 | C12: #378ADD | D12: 流れの速い本流。足を取られる。
A13: ter_shallow | B13: 浅瀬 | C13: #85B7EB | D13: 膝までの流れ。水草と小魚。
... A39: ter_fieldplot | B39: 畑跡 | C39: #C0DD97 | D39: 作物の名残がある耕地の跡。

Sheet Maps
A1: Maps（固定マップ） ― 各エリア 10×10。セルの色＝地形。ここを書き換えれば配置が変わる
A3: 森 （loc_forest）
A4: 樹幹 | B4: 樹幹 | C4: 落ち葉だまり | D4: 落ち葉だまり | E4: 岩場 | F4: 岩場 | G4: 岩場 | H4: 岩場 | I4: 岩場 | J4: 岩場
A5: 樹幹 | B5: 落ち葉だまり | C5: 落ち葉だまり | D5: 落ち葉だまり | E5: 木漏れ日の空き地 | F5: 木漏れ日の空き地 | G5: 草むら | H5: 草むら | I5: 草むら | J5: 岩場
A6: 落ち葉だまり | B6: 落ち葉だまり | C6: 落ち葉だまり | D6: 落ち葉だまり | E6: 木漏れ日の空き地 | F6: 草むら | G6: 草むら | H6: 草むら | I6: 草むら | J6: 草むら
A7: 落ち葉だまり | B7: 落ち葉だまり | C7: 落ち葉だまり | D7: 落ち葉だまり | E7: 木漏れ日の空き地 | F7: 草むら | G7: 草むら | H7: 草むら | I7: 草むら | J7: 草むら
A8: 落ち葉だまり | B8: 落ち葉だまり | C8: 落ち葉だまり | D8: 落ち葉だまり | E8: 木漏れ日の空き地 | F8: 草むら | G8: 草むら | H8: 樹幹 | I8: 樹幹 | J8: 樹幹
A9: 落ち葉だまり | B9: 落ち葉だまり | C9: 落ち葉だまり | D9: 木漏れ日の空き地 | E9: 木漏れ日の空き地 | F9: 草むら | G9: 樹幹 | H9: 樹幹 | I9: 樹幹 | J9: 樹幹
A10: 樹幹 | B10: 樹幹 | C10: 倒木 | D10: 木漏れ日の空き地 | E10: 木漏れ日の空き地 | F10: 木漏れ日の空き地 | G10: 樹幹 | H10: 樹幹 | I10: 岩場 | J10: 樹幹
A11: 樹幹 | B11: 倒木 | C11: 倒木 | D11: 木漏れ日の空き地 | E11: 木漏れ日の空き地 | F11: 低木 | G11: 低木 | H11: 低木 | I11: 樹幹 | J11: 樹幹
A12: 樹幹 | B12: 倒木 | C12: 倒木 | D12: 倒木 | E12: 低木 | F12: 低木 | G12: 低木 | H12: 低木 | I12: 樹幹 | J12: 樹幹
A13: 倒木 | B13: 倒木 | C13: 倒木 | D13: 倒木 | E13: 倒木 | F13: 倒木 | G13: 低木 | H13: 低木 | I13: 低木 | J13: 樹幹
A15: 草原 （loc_meadow）
A16: 草むら | B16: 草むら | C16: 木漏れ日の空き地 | D16: 木漏れ日の空き地 | E16: 木漏れ日の空き地 | F16: 木漏れ日の空き地 | G16: 木漏れ日の空き地 | H16: 草むら | I16: 草むら | J16: 草むら
A17: 草むら | B17: 草むら | C17: 草むら | D17: 木漏れ日の空き地 | E17: 木漏れ日の空き地 | F17: 木漏れ日の空き地 | G17: 木漏れ日の空き地 | H17: 草むら | I17: 草むら | J17: 草むら
A18: 草むら | B18: 草むら | C18: 草むら | D18: 草むら | E18: 木漏れ日の空き地 | F18: 木漏れ日の空き地 | G18: 草むら | H18: 草むら | I18: 草むら | J18: 草むら
A19: 岩場 | B19: 裸地 | C19: 裸地 | D19: 裸地 | E19: 裸地 | F19: 木漏れ日の空き地 | G19: 木漏れ日の空き地 | H19: 木漏れ日の空き地 | I19: 草むら | J19: 草むら
A20: 岩場 | B20: 岩場 | C20: 裸地 | D20: 裸地 | E20: 裸地 | F20: 裸地 | G20: 低木 | H20: 低木 | I20: 低木 | J20: 低木
A21: 岩場 | B21: 岩場 | C21: 岩場 | D21: 裸地 | E21: 裸地 | F21: 裸地 | G21: 草むら | H21: 低木 | I21: 低木 | J21: 草むら
A22: 岩場 | B22: 草むら | C22: 岩場 | D22: 裸地 | E22: 草むら | F22: 草むら | G22: 低木 | H22: 低木 | I22: 低木 | J22: 低木
A23: ぬかるみ | B23: ぬかるみ | C23: ぬかるみ | D23: 草むら | E23: 草むら | F23: 草むら | G23: 低木 | H23: 低木 | I23: 低木 | J23: 低木
A24: ぬかるみ | B24: 草むら | C24: 草むら | D24: 草むら | E24: 草むら | F24: 草むら | G24: 低木 | H24: 低木 | I24: 低木 | J24: 低木
A25: ぬかるみ | B25: ぬかるみ | C25: 草むら | D25: 草むら | E25: 草むら | F25: 草むら | G25: 草むら | H25: 草むら | I25: 低木 | J25: 低木
A27: 洞窟 （loc_cave）
A28: 岩場 | B28: 岩場 | C28: 岩場 | D28: 鉱脈 | E28: 鉱脈 | F28: 鉱脈 | G28: 鉱脈 | H28: 暗がり | I28: 暗がり | J28: 暗がり
A29: 暗がり | B29: 岩場 | C29: 岩場 | D29: 岩場 | E29: 岩場 | F29: 鉱脈 | G29: 鉱脈 | H29: 鉱脈 | I29: 鉱脈 | J29: 鉱脈
A30: 岩場 | B30: 岩場 | C30: 岩場 | D30: 岩場 | E30: 岩場 | F30: 鉱脈 | G30: 鉱脈 | H30: 鉱脈 | I30: 鍾乳石 | J30: 鍾乳石
A31: 岩場 | B31: 岩場 | C31: 岩場 | D31: 岩場 | E31: 岩場 | F31: 岩場 | G31: 鍾乳石 | H31: 鍾乳石 | I31: 鍾乳石 | J31: 鍾乳石
A32: 岩場 | B32: 岩場 | C32: 岩場 | D32: 岩場 | E32: 暗がり | F32: 暗がり | G32: 鍾乳石 | H32: 鍾乳石 | I32: 鍾乳石 | J32: 鍾乳石
A33: 岩場 | B33: 岩場 | C33: 浅瀬 | D33: 浅瀬 | E33: 暗がり | F33: 暗がり | G33: 鍾乳石 | H33: 鍾乳石 | I33: 鍾乳石 | J33: 鍾乳石
A34: 暗がり | B34: 浅瀬 | C34: 浅瀬 | D34: 浅瀬 | E34: 暗がり | F34: 暗がり | G34: 暗がり | H34: 鍾乳石 | I34: 鍾乳石 | J34: 鍾乳石
A35: 暗がり | B35: 暗がり | C35: 暗がり | D35: 浅瀬 | E35: 大岩 | F35: 大岩 | G35: 大岩 | H35: 鍾乳石 | I35: 暗がり | J35: 暗がり
A36: 暗がり | B36: 暗がり | C36: 大岩 | D36: 暗がり | E36: 大岩 | F36: 大岩 | G36: 暗がり | H36: 暗がり | I36: 暗がり | J36: 暗がり
A37: 暗がり | B37: 大岩 | C37: 大岩 | D37: 大岩 | E37: 大岩 | F37: 暗がり | G37: 暗がり | H37: 暗がり | I37: 暗がり | J37: 暗がり
A39: 川辺 （loc_riverside）
A40: 河原 | B40: 河原 | C40: 河原 | D40: 河原 | E40: 河原 | F40: 河原 | G40: 河原 | H40: 川の中 | I40: 川の中 | J40: 川の中
A41: 河原 | B41: 河原 | C41: 河原 | D41: 河原 | E41: 河原 | F41: 河原 | G41: 河原 | H41: 河原 | I41: 川の中 | J41: 川の中
A42: 川の中 | B42: 川の中 | C42: 川の中 | D42: 河原 | E42: 川の中 | F42: 川の中 | G42: 河原 | H42: 河原 | I42: 河原 | J42: 草むら
A43: 川の中 | B43: 岩場 | C43: 河原 | D43: 河原 | E43: ぬかるみ | F43: 川の中 | G43: 草むら | H43: 草むら | I43: 草むら | J43: 草むら
A44: 岩場 | B44: 岩場 | C44: ぬかるみ | D44: 河原 | E44: ぬかるみ | F44: ぬかるみ | G44: 草むら | H44: 草むら | I44: 草むら | J44: 草むら
...

Sheet Items
A2: Items（data_items.js） ― 1行 ＝ 1アイテム
A3: id 例: item_001 | B3: name 日本語名 | C3: categoryId ▼日本語で選択 | D3: categoryId ※自動入力 | E3: effectId 薬効 ▼日本語で選択 | F3: effectId ※自動入力 | G3: reactionId 調合時効果 ▼日本語で選択 | H3: reactionId ※自動入力 | I3: description 説明文 | J3: メモ、採取後更新されるテキスト | K3: 入手方法 採取 / 購入 / 調合 | L3: 基準価格 仮の目安値 | M3: 用途 素材 / 消耗品 / 道具 / 販売品 | N3: 店解禁 累計販売数がこれを超えると 店で買えるようになる | O3: 剤形 液体 / 粉末 / 固形 / 気体 / 素材 | P3: 実装済? ✔を入力
A4: item_001 | B4: ニガタケ | C4: 菌類 | D4: {=IFERROR(INDEX(値リスト!$A$3:$A$9,MATCH(C4,値リスト!$B$3:$B$9,0)),"")} -> fungi | E4: 治癒 | F4: =IFERROR(INDEX(値リスト!$A$14:$A$24,MATCH(E4,値リスト!$B$14:$B$24,0)),"") -> healing | G4: 保存 | H4: =IFERROR(INDEX(値リスト!$A$27:$A$33,MATCH(G4,値リスト!$B$27:$B$33,0)),"") -> preserve | I4: ありふれたキノコ。薬の材料になる。 | J4: 基本素材 よく生えているキノコ。意外なことに薬になるが、味は良くない。火を加えると薬効が高まるが、味もひどく苦くなる。 | K4: 採取 | L4: 8 | M4: 素材 | N4: 200 | O4: 素材
A5: item_002 | B5: ハシリタケ | C5: 菌類 | D5: {=IFERROR(INDEX(値リスト!$A$3:$A$9,MATCH(C5,値リスト!$B$3:$B$9,0)),"")} -> fungi | E5: 興奮 | F5: =IFERROR(INDEX(値リスト!$A$14:$A$24,MATCH(E5,値リスト!$B$14:$B$24,0)),"") -> stimulation | G5: 浸透 | H5: =IFERROR(INDEX(値リスト!$A$27:$A$33,MATCH(G5,値リスト!$B$27:$B$33,0)),"") -> permeate | I5: 夜歩き出すという伝説のあるキノコ | J5: 一晩に数メートルから十数メートル移動するキノコ。いくつかの種類があるが、多量に摂取すると毒となる。少量なら興奮効果をもたらす。 | K5: 採取 | L5: 8 | M5: 素材 | N5: 200 | O5: 素材
A6: item_003 | B6: ニガハシリダケ | C6: 菌類 | D6: {=IFERROR(INDEX(値リスト!$A$3:$A$9,MATCH(C6,値リスト!$B$3:$B$9,0)),"")} -> fungi | E6: 興奮 | F6: =IFERROR(INDEX(値リスト!$A$14:$A$24,MATCH(E6,値リスト!$B$14:$B$24,0)),"") -> stimulation | G6: 揮発 | H6: =IFERROR(INDEX(値リスト!$A$27:$A$33,MATCH(G6,値リスト!$B$27:$B$33,0)),"") -> volatile | I6: ニガタケによく似ているが、現れては消えて夜の旅人の道行を惑わすという。 | J6: ニガタケによく似たハシリダケの一種。どこにでも見かけるキノコ、ニガタケに紛れて見つけにくい。ハシリダケの一種であるため、一晩に十メートル前後移動するが、じっと見つめていないとわからないため見つけにくい。キノコを目印にした旅人を惑わす。 とれる場所：森 林 取れる時間帯：夜は確率が上がる。昼はニガタケにまじってまれに取れることがある。 調合のヒント：ニガタケとハシリタケの特性を持つが、鮮度が落ちるのが速い。 | K6: 採取 | L6: 8 | M6: 素材 | O6: 素材
A7: item_004 | B7: ドロワリタケ | C7: 菌類 | D7: {=IFERROR(INDEX(値リスト!$A$3:$A$9,MATCH(C7,値リスト!$B$3:$B$9,0)),"")} -> fungi | E7: 滋養強壮 | F7: =IFERROR(INDEX(値リスト!$A$14:$A$24,MATCH(E7,値リスト!$B$14:$B$24,0)),"") -> tonic | G7: 触媒 | H7: =IFERROR(INDEX(値リスト!$A$27:$A$33,MATCH(G7,値リスト!$B$27:$B$33,0)),"") -> catalyst | I7: 沼地の泥炭層から生える黒くて平たいキノコ。水分を非常に多く含む。 | J7: 泥の中ではその姿を捉えることは叶わないが、採取し洗ってみれば、泥炭の養分を凝縮したような漆黒の弾力が現れる。滋養強壮の薬として名高いが、真に驚くべきはその「触媒」としての力だ。このキノコを釜に投じれば、一夜で成長するその生命力が、本来は反応の遅い重い素材同士を強引に結びつけ、変化の時を早めてくれる。 | K7: 採取 | L7: 8 | M7: 素材 | N7: 200 | O7: 素材
A8: item_005 | B8: ヌメリヒラタケ | C8: 菌類 | D8: {=IFERROR(INDEX(値リスト!$A$3:$A$9,MATCH(C8,値リスト!$B$3:$B$9,0)),"")} -> fungi | E8: 解毒 | F8: =IFERROR(INDEX(値リスト!$A$14:$A$24,MATCH(E8,値リスト!$B$14:$B$24,0)),"") -> detox | G8: 分離 | H8: =IFERROR(INDEX(値リスト!$A$27:$A$33,MATCH(G8,値リスト!$B$27:$B$33,0)),"") -> separate | I8: 腐った倒木に群生し、分解力が強い。 | J8: 常に纏っている灰色の粘液は、倒木を分解し尽くす強欲な生命力の表れだ。この粘液は、調合において「分離」の力を発揮する。薬液に含まれる不要な濁りや、素材が持つ雑多な魔力をこの粘液が絡め取り、純粋な成分だけを鮮やかに切り離してくれる。化粧品に使われるのは、その清浄なまでの分解力ゆえだろう。 | K8: 採取 | L8: 8 | M8: 素材 | N8: 200 | O8: 素材
A9: item_006 | B9: ヤセボソシメジ | C9: 菌類 | D9: {=IFERROR(INDEX(値リスト!$A$3:$A$9,MATCH(C9,値リスト!$B$3:$B$9,0)),"")} -> fungi | E9: 治癒 | F9: =IFERROR(INDEX(値リスト!$A$14:$A$24,MATCH(E9,値リスト!$B$14:$B$24,0)),"") -> healing | G9: 触媒 | H9: =IFERROR(INDEX(値リスト!$A$27:$A$33,MATCH(G9,値リスト!$B$27:$B$33,0)),"") -> catalyst | I9: 針葉樹の根元にひっそりと生える。見た目に反して旨味が強く、出汁によく出る。 | J9: 針葉樹の影で今にも折れそうな姿をしているが、その身には驚くほどの「溶けやすさ」を秘めている。熱を加えた瞬間、形を失って薬液に溶け込み、周囲の素材の旨味と力を一つに束ね上げる。頑固で混ざり合わない素材同士を繋ぐその様子は、弱々しい見た目に反して、調合釜の中では誰よりも優れた「仲介役」となる。 | K9: 採取 | L9: 8 | M9: 素材 | N9: 200 | O9: 素材
A10: item_007 | B10: ウロコモドキ | C10: 菌類 | D10: {=IFERROR(INDEX(値リスト!$A$3:$A$9,MATCH(C10,値リスト!$B$3:$B$9,0)),"")} -> fungi | E10: 鎮静 | F10: =IFERROR(INDEX(値リスト!$A$14:$A$24,MATCH(E10,値リスト!$B$14:$B$24,0)),"") -> sedation | G10: 凝固 | H10: =IFERROR(INDEX(値リスト!$A$27:$A$33,MATCH(G10,値リスト!$B$27:$B$33,0)),"") -> coagulate | I10: 傘の表面が魚の鱗のように硬質化したキノコ。すりつぶすと研磨剤のような粉になる。 | J10: 傘の表面を覆う魚の鱗は、石のように硬く、並の刃では傷一つつかない。しかし、これを根気よくすりつぶして粉末にすれば、液体を瞬時に「凝固」させる強力な固め剤となる。滴るような薬液を、持ち運びやすい丸薬や固形へと変容させる際、このキノコの持つ「守りの硬さ」が役立つのだ。 | K10: 採取 | L10: 8 | M10: 素材 | N10: 200 | O10: 素材
A11: item_008 | B11: カビツキヌメリ | C11: 菌類 | D11: {=IFERROR(INDEX(値リスト!$A$3:$A$9,MATCH(C11,値リスト!$B$3:$B$9,0)),"")} -> fungi | E11: 猛毒 | F11: =IFERROR(INDEX(値リスト!$A$14:$A$24,MATCH(E11,値リスト!$B$14:$B$24,0)),"") -> poison | G11: 触媒 | H11: =IFERROR(INDEX(値リスト!$A$27:$A$33,MATCH(G11,値リスト!$B$27:$B$33,0)),"") -> catalyst | I11: 他のキノコに寄生する白い菌。強い「発酵」を促す成分がある。 | J11: 他の菌を侵食し、その性質を根底から書き換えてしまう寄生菌。採取した後は、この白い菌が持つ恐るべき「浸透」の力だけを利用する。一緒に入れた素材の核にある力を強制的に引き出し、ベースとなる水へと移し替えてしまう。その力は、まるで他の素材の魂を水へと溶かし出すかのようだ。 | K11: 採取 | L11: 8 | M11: 素材 | O11: 素材
A12: item_009 | B12: スナボコリタケ | C12: 菌類 | D12: {=IFERROR(INDEX(値リスト!$A$3:$A$9,MATCH(C12,値リスト!$B$3:$B$9,0)),"")} -> fungi | E12: なし | F12: =IFERROR(INDEX(値リスト!$A$14:$A$24,MATCH(E12,値リスト!$B$14:$B$24,0)),"") -> none | G12: 揮発 | H12: =IFERROR(INDEX(値リスト!$A$27:$A$33,MATCH(G12,値リスト!$B$27:$B$33,0)),"") -> volatile | I12: 乾燥した砂地に生える。衝撃を与えると細かい胞子（粉末）を噴き出す。 | J12: 衝撃を与えれば最後、このキノコは一瞬で胞子の煙へと化す。この「揮発」しやすさは、調合においても最大の難所となる。熱を加えすぎれば、丹精込めた薬効もすべて煙となって消えてしまうだろう。薬の力を空気へと逃がさないよう、調合の最後にそっと加える繊細な手捌きが求められる。 | K12: 採取 | L12: 8 | M12: 素材 | N12: 200 | O12: 素材
A13: item_010 | B13: ベニテングダマシ | C13: 菌類 | D13: {=IFERROR(INDEX(値リスト!$A$3:$A$9,MATCH(C13,値リスト!$B$3:$B$9,0)),"")} -> fungi | E13: 解毒 | F13: =IFERROR(INDEX(値リスト!$A$14:$A$24,MATCH(E13,値リスト!$B$14:$B$24,0)),"") -> detox | G13: 中和 | H13: =IFERROR(INDEX(値リスト!$A$27:$A$33,MATCH(G13,値リスト!$B$27:$B$33,0)),"") -> neutralize | I13: 毒キノコにそっくりだが毒はない。非常に苦く、「良薬口に苦し」を体現する。 | J13: 猛毒のベニテングタケを模したその姿は、自らを守るための嘘に過ぎない。実際には毒などなく、ただただ閉口するほどに苦い。しかし、その「良薬口に苦し」を地で行く強烈な苦味は、他の素材が持つ尖った毒性を打ち消す「中和」の力を秘めている。偽物が本物を制する、奇妙な調和をもたらすキノコだ。 | K13: 採取 | L13: 8 | M13: 素材 | N13: 200 | O13: 素材
A14: item_011 | B14: クサリフフダケ | C14: 菌類 | D14: {=IFERROR(INDEX(値リスト!$A$3:$A$9,MATCH(C14,値リスト!$B$3:$B$9,0)),"")} -> fungi | E14: 解毒 | F14: =IFERROR(INDEX(値リスト!$A$14:$A$24,MATCH(E14,値リスト!$B$14:$B$24,0)),"") -> detox | G14: 中和 | H14: =IFERROR(INDEX(値リスト!$A$27:$A$33,MATCH(G14,値リスト!$B$27:$B$33,0)),"") -> neutralize | I14: 腐肉の近くに生える独特の臭気を放つキノコ。解毒剤の反転素材として使われる。 | J14: 腐肉の傍らでその臭気を吸って育つこのキノコは、死の際にある素材を好む。通常、毒を消すために使われる素材だが、その本質は「反転」にある。清浄な薬液をあえて腐敗の淵へと追い込み、極限の状態で見せる「毒をもって毒を制する」という危うい解毒の道行へ、調合者を誘う。 | K14: 採取 | L14: 8 | M14: 素材 | N14: 200 | O14: 素材
A15: item_012 | B15: ネバリイグチ | C15: 菌類 | D15: {=IFERROR(INDEX(値リスト!$A$3:$A$9,MATCH(C15,値リスト!$B$3:$B$9,0)),"")} -> fungi | E15: なし | F15: =IFERROR(INDEX(値リスト!$A$14:$A$24,MATCH(E15,値リスト!$B$14:$B$24,0)),"") -> none | G15: 凝固 | H15: =IFERROR(INDEX(値リスト!$A$27:$A$33,MATCH(G15,値リスト!$B$27:$B$33,0)),"") -> coagulate | I15: 松林の地中に埋まって生える。掘り起こすと強烈な粘り気があり、接合剤の役割を果たす。 | J15: 地中に隠れたその身を掘り起こせば、糸を引くような強烈な粘り気が手につく。この粘りこそが、バラバラな成分を繋ぎ止める「凝固」の源泉だ。熱を加えてもその粘りは失われず、接合剤として薬を一つにまとめ上げ、完成した薬の形を永く保つための楔となる。 | K15: 採取 | L15: 8 | M15: 素材 | N15: 200 | O15: 素材
A16: item_013 | B16: シロガネタケ | C16: 菌類 | D16: {=IFERROR(INDEX(値リスト!$A$3:$A$9,MATCH(C16,値リスト!$B$3:$B$9,0)),"")} -> fungi | E16: 防護 | F16: =IFERROR(INDEX(値リスト!$A$14:$A$24,MATCH(E16,値リスト!$B$14:$B$24,0)),"") -> insulation | G16: 保存 | H16: =IFERROR(INDEX(値リスト!$A$27:$A$33,MATCH(G16,値リスト!$B$27:$B$33,0)),"") -> preserve | I16: 高山の岩肌にへばりつく白く乾いたキノコ。極寒に耐える性質（耐冷性）を持つ。 | J16: 高山の凍てつく岩肌で、白く乾いたまま時を止めている。極寒に耐えうるその性質は、採取後も失われない。調合液にこのシロガネタケを加えれば、その「保存」の力が熱による劣化を防ぎ、薬の鮮度を雪の中に閉じ込めたかのように瑞々しく保ってくれる。 | K16: 採取 | L16: 8 | M16: 素材 | O16: 素材
A17: item_014 | B17: ホウオウノハネ | C17: 菌類 | D17: {=IFERROR(INDEX(値リスト!$A$3:$A$9,MATCH(C17,値リスト!$B$3:$B$9,0)),"")} -> fungi | E17: 興奮 | F17: =IFERROR(INDEX(値リスト!$A$14:$A$24,MATCH(E17,値リスト!$B$14:$B$24,0)),"") -> stimulation | G17: 触媒 | H17: =IFERROR(INDEX(値リスト!$A$27:$A$33,MATCH(G17,値リスト!$B$27:$B$33,0)),"") -> catalyst | I17: 深紅と金色のグラデーションを持つ扇状のキノコ。煮出すと燃えるような熱を持つ。 | J17: 煮出すと、まるで鳳凰の羽ばたきのように、釜の中に燃えるような熱が広がる。このキノコ自体が激しい変化を促す「触媒」であり、本来は決して混ざり合うことのない水と油、あるいは対立する属性の素材を、熱の奔流によって強引に融和させてしまう。 | K17: 採取 | L17: 8 | M17: 素材 | O17: 素材
B18: ユウヒダケ | C18: 菌類 | E18: 防護 | G18: 触媒 | I18: 夕暮れ時にのみ赤く発光するキノコ。 | J18: 光を蓄える性質があり、乾燥させて粉にすると火を近づけずとも激しく反応する。それ自体が変化の火種となる「触媒」の性質を持ち、本来は混ざり合わない油と水のような素材を強引に反応させる力がある。
A19: item_015 | B19: ミズギワソウ | C19: 植物 | D19: {=IFERROR(INDEX(値リスト!$A$3:$A$9,MATCH(C19,値リスト!$B$3:$B$9,0)),"")} -> flora | E19: 解毒 | F19: =IFERROR(INDEX(値リスト!$A$14:$A$24,MATCH(E19,値リスト!$B$14:$B$24,0)),"") -> detox | G19: 分離 | H19: =IFERROR(INDEX(値リスト!$A$27:$A$33,MATCH(G19,値リスト!$B$27:$B$33,0)),"") -> separate | I19: 川の合流地点にのみ自生する。茎がストロー状で、不純物を濾過する性質がある。 | J19: 川の合流地点で、二つの異なる水流から魔力を選別して吸収している。ストロー状の茎は「不純な魔力」を濾過する天然のフィルターであり、調合液を通すことで、毒性や雑味だけを鮮やかに「分離」することができる。 | K19: 採取 | L19: 8 | M19: 素材 | N19: 200 | O19: 素材
A20: item_016 | B20: イバラアザミ | C20: 植物 | D20: {=IFERROR(INDEX(値リスト!$A$3:$A$9,MATCH(C20,値リスト!$B$3:$B$9,0)),"")} -> flora | E20: 治癒 | F20: =IFERROR(INDEX(値リスト!$A$14:$A$24,MATCH(E20,値リスト!$B$14:$B$24,0)),"") -> healing | G20: 浸透 | H20: =IFERROR(INDEX(値リスト!$A$27:$A$33,MATCH(G20,値リスト!$B$27:$B$33,0)),"") -> permeate | I20: 鋭いトゲを持つ野草。傷をたちどころに治すという伝説がある。 | J20: 鋭いトゲは魔を払う力を持つ。根に蓄えられた瑞々しい液は、生命力の奔流そのもの。切り口から滴る白い液は、傷口に触れると凝固して瞬時に傷を塞ぐ。内臓の傷をも癒やすという伝説は、止血効果によるもの。 | K20: 採取 | L20: 8 | M20: 素材 | N20: 200 | O20: 素材
A21: item_017 | B21: カサカサ草 | C21: 植物 | D21: {=IFERROR(INDEX(値リスト!$A$3:$A$9,MATCH(C21,値リスト!$B$3:$B$9,0)),"")} -> flora | E21: なし | F21: =IFERROR(INDEX(値リスト!$A$14:$A$24,MATCH(E21,値リスト!$B$14:$B$24,0)),"") -> none | G21: 揮発 | H21: =IFERROR(INDEX(値リスト!$A$27:$A$33,MATCH(G21,値リスト!$B$27:$B$33,0)),"") -> volatile | I21: 一年中枯れたような茶褐色の葉を持つ。油分を多く含み、火種（着火材）に最適。 | J21: 乾ききった茶褐色の葉には、指で触れるだけで油がにじむ。この油こそが、調合における「揮発」の源泉だ。熱を加えた瞬間、葉は白い煙となって一息に気化し、混ぜ合わせた素材の成分を空気へと引き連れていく。気体薬や燻し薬を作る際の着火剤として、調合者たちが重宝する草だ。 | K21: 採取 | L21: 8 | M21: 素材 | N21: 200 | O21: 素材
A22: item_018 | B22: オオツユグサ | C22: 植物 | D22: {=IFERROR(INDEX(値リスト!$A$3:$A$9,MATCH(C22,値リスト!$B$3:$B$9,0)),"")} -> flora | E22: 鎮静 | F22: =IFERROR(INDEX(値リスト!$A$14:$A$24,MATCH(E22,値リスト!$B$14:$B$24,0)),"") -> sedation | G22: 凝固 | H22: =IFERROR(INDEX(値リスト!$A$27:$A$33,MATCH(G22,値リスト!$B$27:$B$33,0)),"") -> coagulate | I22: 早朝、葉の縁に大きな雫を溜める性質がある。水が貴重な場所での水源。 | J22: 夜明け前、葉の縁にぷるりと膨らむ大粒の雫は、一日のうちで最も静謐な時間を閉じ込めている。この雫を集めて薬液に加えれば、昂った成分の動きを宥め、ゆっくりと「凝固」させる穏やかな力を発揮する。荒ぶる素材を落ち着かせ、一つの形にまとめる、夜明けの静けさを纏った草だ。 | K22: 採取 | L22: 8 | M22: 素材 | N22: 200 | O22: 素材
A23: item_019 | B23: ニガヨモギモドキ | C23: 植物 | D23: {=IFERROR(INDEX(値リスト!$A$3:$A$9,MATCH(C23,値リスト!$B$3:$B$9,0)),"")} -> flora | E23: 治癒 | F23: =IFERROR(INDEX(値リスト!$A$14:$A$24,MATCH(E23,値リスト!$B$14:$B$24,0)),"") -> healing | G23: 浸透 | H23: =IFERROR(INDEX(値リスト!$A$27:$A$33,MATCH(G23,値リスト!$B$27:$B$33,0)),"") -> permeate | I23: 非常に香りが強く、虫除けに使われる。乾燥させて煎じると腹痛に効く。 | J23: その強烈な香気は、触れるものすべての奥深くへと染み入っていく。煎じれば腹の底まで温もりが「浸透」し、痛みの根を解きほぐす。虫すら寄せ付けぬその気を薬液に宿すことで、塗り薬や吸引薬の効果を皮の奥まで届ける媒介となる。刺激的な香りの裏に、静かで深い癒しの力を持つ草だ。 | K23: 採取 | L23: 8 | M23: 素材 | N23: 200 | O23: 素材
A24: item_020 | B24: イワノボリツル | C24: 植物 | D24: {=IFERROR(INDEX(値リスト!$A$3:$A$9,MATCH(C24,値リスト!$B$3:$B$9,0)),"")} -> flora | E24: 防護 | F24: =IFERROR(INDEX(値リスト!$A$14:$A$24,MATCH(E24,値リスト!$B$14:$B$24,0)),"") -> insulation | G24: 凝固 | H24: =IFERROR(INDEX(値リスト!$A$27:$A$33,MATCH(G24,値リスト!$B$27:$B$33,0)),"") -> coagulate | I24: 岩壁を這うように伸びる強靭なツル。繊維が丈夫で、煮出すと丈夫な紐になる。 | J24: 岩の割れ目に爪を立てるようにして這い上がるその繊維は、引いても切れず、曲げても折れない。調合釜に投じれば、ばらばらに漂う成分を繊維で絡め取るように「凝固」させ、頑丈な薬の形を作り上げる。その丈夫さが体を守る「防護」の薬効へと転じ、傷口や患部を外の脅威から遮断する盾となる。 | K24: 採取 | L24: 8 | M24: 素材 | N24: 200 | O24: 素材
A25: item_021 | B25: ツボミカズラ | C25: 植物 | D25: {=IFERROR(INDEX(値リスト!$A$3:$A$9,MATCH(C25,値リスト!$B$3:$B$9,0)),"")} -> flora | E25: 滋養強壮 | F25: =IFERROR(INDEX(値リスト!$A$14:$A$24,MATCH(E25,値リスト!$B$14:$B$24,0)),"") -> tonic | G25: 保存 | H25: =IFERROR(INDEX(値リスト!$A$27:$A$33,MATCH(G25,値リスト!$B$27:$B$33,0)),"") -> preserve | I25: 花が開かず、蕾のまま結実する珍しい植物。栄養が凝縮されている。 | J25: 花開くことを拒み、すべての栄養を蕾の中に凝縮させたまま結実する蔓植物。その内に秘められた強烈な生命力は、調合において「保存 」の気質として現れる。完成した薬の中に、この蕾に閉じ込められた「時」を分け与えることで、薬効が腐敗するのを防ぎ、長きにわたってその力を維持させる 。 | K25: 採取 | L25: 8 | M25: 素材 | N25: 200 | O25: 素材
A26: item_022 | B26: ハッカガヤ | C26: 植物 | D26: {=IFERROR(INDEX(値リスト!$A$3:$A$9,MATCH(C26,値リスト!$B$3:$B$9,0)),"")} -> flora | E26: 治癒 | F26: =IFERROR(INDEX(値リスト!$A$14:$A$24,MATCH(E26,値リスト!$B$14:$B$24,0)),"") -> healing | G26: 浸透 | H26: =IFERROR(INDEX(値リスト!$A$27:$A$33,MATCH(G26,値リスト!$B$27:$B$33,0)),"") -> permeate | I26: 踏むと爽やかな香りが広がる草原の草。清涼感があり、熱を冷ます効果がある。 | J26: 踏みしめるたびに清涼な香気が立ち上るこの草は、冷たさを肌の奥へと送り込む力を持つ。その香りを薬液に移せば、「浸透」の気質として表れ、熱を帯びた患部の深部まで癒しの冷気を届ける。熱病や炎症を和らげる薬において、効果を体の芯まで届ける道案内の役を担う。 | K26: 採取 | L26: 8 | M26: 素材 | N26: 200 | O26: 素材
A27: item_023 | B27: ネバリダイコン | C27: 植物 | D27: {=IFERROR(INDEX(値リスト!$A$3:$A$9,MATCH(C27,値リスト!$B$3:$B$9,0)),"")} -> flora | E27: 滋養強壮 | F27: =IFERROR(INDEX(値リスト!$A$14:$A$24,MATCH(E27,値リスト!$B$14:$B$24,0)),"") -> tonic | G27: 保存 | H27: =IFERROR(INDEX(値リスト!$A$27:$A$33,MATCH(G27,値リスト!$B$27:$B$33,0)),"") -> preserve | I27: 砂地に深く刺さった細長い根。水分を蓄える力が強く、保湿剤の原料になる。 | J27: 砂漠の乾燥に抗い、砂の奥深くに水分を抱えたまま生き延びるこの根は、強靭な生命力の塊だ。調合液に加えれば、その「保存」の力が薬液全体に行き渡り、他の素材が揮発したり腐敗するのを防ぐ。同時に凝縮された滋養が「滋養強壮」として肉体の疲弊を回復させる、砂漠の恵みだ。 | K27: 採取 | L27: 8 | M27: 素材 | N27: 200 | O27: 素材
A28: item_024 | B28: ミツユキソウ | C28: 植物 | D28: {=IFERROR(INDEX(値リスト!$A$3:$A$9,MATCH(C28,値リスト!$B$3:$B$9,0)),"")} -> flora | E28: 神秘 | F28: =IFERROR(INDEX(値リスト!$A$14:$A$24,MATCH(E28,値リスト!$B$14:$B$24,0)),"") -> mystic | G28: 保存 | H28: =IFERROR(INDEX(値リスト!$A$27:$A$33,MATCH(G28,値リスト!$B$27:$B$33,0)),"") -> preserve | I28: 雪解けのわずかな期間にのみ姿を現す白い花。 | J28: 雪解けの一瞬だけ顔を出し、また雪の下へと戻っていくこの花は、時間そのものを凝らせたような白さをしている。摘み取った瞬間から時が止まるかのようにその姿を保ち、調合液の中でも「保存」の力として働き、薬の劣化を長く拒む。その稀少な咲き方が宿す不思議な力は、魔力回路を一時的に開く「神秘」の薬効をもたらす。 | K28: 採取 | L28: 8 | M28: 素材 | O28: 素材
A29: item_025 | B29: リュウノツノ | C29: 植物 | D29: {=IFERROR(INDEX(値リスト!$A$3:$A$9,MATCH(C29,値リスト!$B$3:$B$9,0)),"")} -> flora | E29: 安定 | F29: =IFERROR(INDEX(値リスト!$A$14:$A$24,MATCH(E29,値リスト!$B$14:$B$24,0)),"") -> stable | G29: 凝固 | H29: =IFERROR(INDEX(値リスト!$A$27:$A$33,MATCH(G29,値リスト!$B$27:$B$33,0)),"") -> coagulate | I29: 砂漠の岩場に突き出た、ねじれた硬い枝。バラバラな成分を固める性質がある。 | J29: 砂漠の過酷な乾燥に耐え、石のようにねじ曲がったその枝は、バラバラな属性を一つに束ねる「凝固」の力を象徴している。この硬い枝を砕いて投じれば、水に溶け出そうとする不安定な成分を物理的に絡め取り、一つの安定した霊薬へと形を成さしめる。 | K29: 採取 | L29: 8 | M29: 素材 | O29: 素材
A30: item_026 | B30: オロチノイバラ | C30: 植物 | D30: {=IFERROR(INDEX(値リスト!$A$3:$A$9,MATCH(C30,値リスト!$B$3:$B$9,0)),"")} -> flora | E30: 猛毒 | F30: =IFERROR(INDEX(値リスト!$A$14:$A$24,MATCH(E30,値リスト!$B$14:$B$24,0)),"") -> poison | G30: 分離 | H30: =IFERROR(INDEX(値リスト!$A$27:$A$33,MATCH(G30,値リスト!$B$27:$B$33,0)),"") -> separate | I30: 八方にうねるように伸びる猛毒の蔓。硬い素材を溶かして分解するという。 | J30: 八方にのたうつ猛毒の蔓は、獲物を締め上げるのではなく「溶かして喰らう」ためのものだ。調合においても、その破壊的な「分離」の力は健在である。どんなに硬い鉱石であっても、この蔓と共に煮れば成分が解きほぐされ、必要な力だけを抽出することができる。 | K30: 採取 | L30: 8 | M30: 素材 | O30: 素材
A31: item_027 | B31: 青泥石 | C31: 鉱物 | D31: {=IFERROR(INDEX(値リスト!$A$3:$A$9,MATCH(C31,値リスト!$B$3:$B$9,0)),"")} -> mineral | E31: 鎮静 | F31: =IFERROR(INDEX(値リスト!$A$14:$A$24,MATCH(E31,値リスト!$B$14:$B$24,0)),"") -> sedation | G31: 保存 | H31: =IFERROR(INDEX(値リスト!$A$27:$A$33,MATCH(G31,値リスト!$B$27:$B$33,0)),"") -> preserve | I31: 底なし沼の深くから採れる、青みがかった粘土質の石。熱を逃がさない。 | J31: 底なし沼の深みで、長い年月をかけて熱を溜め込んだ青みがかった粘土は、触れると不思議な温もりを持つ。この熱を手放さない性質が調合において「保存」の力として現れ、完成した薬の温かさと効能を逃がさず閉じ込める。また、その深く静かな粘土の重さは昂った気を沈め、「鎮静」の薬効として作用する。 | K31: 採取 | L31: 8 | M31: 素材 | N31: 200 | O31: 素材
A32: item_028 | B32: 火打ち斑岩 | C32: 鉱物 | D32: {=IFERROR(INDEX(値リスト!$A$3:$A$9,MATCH(C32,値リスト!$B$3:$B$9,0)),"")} -> mineral | E32: 興奮 | F32: =IFERROR(INDEX(値リスト!$A$14:$A$24,MATCH(E32,値リスト!$B$14:$B$24,0)),"") -> stimulation | G32: 揮発 | H32: =IFERROR(INDEX(値リスト!$A$27:$A$33,MATCH(G32,値リスト!$B$27:$B$33,0)),"") -> volatile | I32: 鉄分を多く含んだ黒い石。叩くと火花が出やすく、加工が難しい。 | J32: 叩けば容赦なく火花を散らすこの黒い石は、そのままでは調合者の手を焦がす厄介者だ。しかし、この爆発的な反応こそが「揮発」の源泉となる。薬液に加えた瞬間、溶け出した鉄分が熱との触媒となり、成分を一気に気化させる。その烈しい弾けるような力が「興奮」の薬効として、摂取者の血を沸き立たせる。 | K32: 採取 | L32: 8 | M32: 素材 | N32: 200 | O32: 素材
A33: item_029 | B33: 白砂晶 | C33: 鉱物 | D33: {=IFERROR(INDEX(値リスト!$A$3:$A$9,MATCH(C33,値リスト!$B$3:$B$9,0)),"")} -> mineral | E33: 解毒 | F33: =IFERROR(INDEX(値リスト!$A$14:$A$24,MATCH(E33,値リスト!$B$14:$B$24,0)),"") -> detox | G33: 分離 | H33: =IFERROR(INDEX(値リスト!$A$27:$A$33,MATCH(G33,値リスト!$B$27:$B$33,0)),"") -> separate | I33: 砂漠の砂が固まってできた脆い結晶。水に溶けやすく、溶媒の性質を変える。 | J33: 砂漠の砂が幾千年もかけて圧縮されたこの脆い結晶は、水に触れるや否や音もなく溶け消える。その溶けやすさは「分離」の力として現れ、薬液の中に潜む有害な成分だけを自ら引き受けて溶かし込み、無害な物質として流し去る。静かに消えていく様子は、毒を呑んで逝くようでもある。 | K33: 採取 | L33: 8 | M33: 素材 | N33: 200 | O33: 素材
A34: item_030 | B34: 黄土塊 | C34: 鉱物 | D34: {=IFERROR(INDEX(値リスト!$A$3:$A$9,MATCH(C34,値リスト!$B$3:$B$9,0)),"")} -> mineral | E34: 滋養強壮 | F34: =IFERROR(INDEX(値リスト!$A$14:$A$24,MATCH(E34,値リスト!$B$14:$B$24,0)),"") -> tonic | G34: 触媒 | H34: =IFERROR(INDEX(値リスト!$A$27:$A$33,MATCH(G34,値リスト!$B$27:$B$33,0)),"") -> catalyst | I34: 栄養豊富な土壌が固まったもの。肥料の主原料や、土属性の触媒になる。 | J34: 肥沃な大地の恵みが固まったこの塊は、土の記憶そのものだ。調合釜に投じれば、大地が草木を育てるように、周囲の素材の反応を活性化させる「触媒」として働く。豊富なミネラルと生命の養分は「滋養強壮」の薬効として肉体を内側から満たし、枯れかけた力を土が芽吹きを促すように引き出す。 | K34: 採取 | L34: 8 | M34: 素材 | N34: 200 | O34: 素材
A35: item_031 | B35: 墨痕石 | C35: 鉱物 | D35: {=IFERROR(INDEX(値リスト!$A$3:$A$9,MATCH(C35,値リスト!$B$3:$B$9,0)),"")} -> mineral | E35: 解毒 | F35: =IFERROR(INDEX(値リスト!$A$14:$A$24,MATCH(E35,値リスト!$B$14:$B$24,0)),"") -> detox | G35: 分離 | H35: =IFERROR(INDEX(値リスト!$A$27:$A$33,MATCH(G35,値リスト!$B$27:$B$33,0)),"") -> separate | I35: 触ると手が黒くなる、炭に近い鉱石。不純物を吸着する性質がある。 | J35: 触れた端から黒い汚れを残すこの石は、世界の汚れを自ら引き受ける性質を持つ。不純物を吸着し、透明な水へと変えるその「分離」の力は、毒を濾し取るための「解毒」工程において、他のどの素材よりも信頼のおけるフィルターとなるだろう。 | K35: 採取 | L35: 8 | M35: 素材 | N35: 200 | O35: 素材
A36: item_032 | B36: 氷晶石モドキ | C36: 鉱物 | D36: {=IFERROR(INDEX(値リスト!$A$3:$A$9,MATCH(C36,値リスト!$B$3:$B$9,0)),"")} -> mineral | E36: 鎮静 | F36: =IFERROR(INDEX(値リスト!$A$14:$A$24,MATCH(E36,値リスト!$B$14:$B$24,0)),"") -> sedation | G36: 保存 | H36: =IFERROR(INDEX(値リスト!$A$27:$A$33,MATCH(G36,値リスト!$B$27:$B$33,0)),"") -> preserve | I36: 常にひんやりとしている、半透明の石。地下深くの冷気が溜まる場所に存在する。 | J36: 地の底の凍った闇の中で、永い眠りにつくように時を過ごしてきた半透明の石。その芯に宿る冷気は採取後も失われず、薬液の温度を緩やかに下げ続ける。熱による劣化を防ぐ「保存」の力として、薬の鮮度を封じ込める。触れるだけで昂ぶりが静まるような冷たさは、「鎮静」の薬効として精神の熱を和らげる。 | K36: 採取 | L36: 8 | M36: 素材 | O36: 素材
A37: item_033 | B37: 錆び鉄鉱 | C37: 鉱物 | D37: {=IFERROR(INDEX(値リスト!$A$3:$A$9,MATCH(C37,値リスト!$B$3:$B$9,0)),"")} -> mineral | E37: 安定 | F37: =IFERROR(INDEX(値リスト!$A$14:$A$24,MATCH(E37,値リスト!$B$14:$B$24,0)),"") -> stable | G37: 触媒 | H37: =IFERROR(INDEX(値リスト!$A$27:$A$33,MATCH(G37,値リスト!$B$27:$B$33,0)),"") -> catalyst | I37: 酸化が進んだ鉄の塊。煮出すと染料や特殊な反応剤になる。 | J37: 長い年月をかけて酸化し、表面が深い赤褐色に染まったこの鉄の塊は、すでに変化を終えた素材だ。煮出せば澄んだ赤い汁が滲み出し、「触媒」として他の素材の反応を引き出す媒介となる。自身はもはや変化せず、周囲の成分を「安定」した反応へと導く、静かな存在だ。 | K37: 採取 | L37: 8 | M37: 素材 | N37: 200 | O37: 素材
A38: item_034 | B38: 雲母片岩 | C38: 鉱物 | D38: {=IFERROR(INDEX(値リスト!$A$3:$A$9,MATCH(C38,値リスト!$B$3:$B$9,0)),"")} -> mineral | E38: 防護 | F38: =IFERROR(INDEX(値リスト!$A$14:$A$24,MATCH(E38,値リスト!$B$14:$B$24,0)),"") -> insulation | G38: 保存 | H38: =IFERROR(INDEX(値リスト!$A$27:$A$33,MATCH(G38,値リスト!$B$27:$B$33,0)),"") -> preserve | I38: 薄く剥がれやすい性質を持つ石。耐熱性が高く、調合釜のライナーに使われる。 | J38: 爪の先でそっと触れれば、紙のように薄い層が次々と剥がれていく。しかしその一枚一枚は、調合釜の熱すら通さない頑強な盾だ。薬液に溶かせば、鎧のように他の成分を包み込んで「保存」し、外部の熱や湿気から守り抜く。飲み込んだ体の内側でも膜を張り、属性ダメージを遮断する「防護」として働く。 | K38: 採取 | L38: 8 | M38: 素材 | N38: 200 | O38: 素材
A39: item_035 | B39: 潮石 | C39: 鉱物 | D39: {=IFERROR(INDEX(値リスト!$A$3:$A$9,MATCH(C39,値リスト!$B$3:$B$9,0)),"")} -> mineral | E39: 滋養強壮 | F39: =IFERROR(INDEX(値リスト!$A$14:$A$24,MATCH(E39,値リスト!$B$14:$B$24,0)),"") -> tonic | G39: 浸透 | H39: =IFERROR(INDEX(値リスト!$A$27:$A$33,MATCH(G39,値リスト!$B$27:$B$33,0)),"") -> permeate | I39: 昔、海だった場所が隆起してできた岩塩の一種。ミネラル分が極めて高い。 | J39: かつて海の底だったこの場所に積もった塩の記憶が、長い年月をかけて石となった。舐めれば古い海のすべての滋養が舌に広がり、その豊富なミネラルが「滋養強壮」の薬効として肉体の隅々まで染み渡る。水に溶かせば塩が自然と素材に食い込む「浸透」の力となり、他の薬効を体の深くへと届ける塩の道となる。 | K39: 採取 | L39: 8 | M39: 素材 | N39: 200 | O39: 素材
A40: item_036 | B40: 鈍色金 | C40: 鉱物 | D40: {=IFERROR(INDEX(値リスト!$A$3:$A$9,MATCH(C40,値リスト!$B$3:$B$9,0)),"")} -> mineral | E40: 安定 | F40: =IFERROR(INDEX(値リスト!$A$14:$A$24,MATCH(E40,値リスト!$B$14:$B$24,0)),"") -> stable | G40: 凝固 | H40: =IFERROR(INDEX(値リスト!$A$27:$A$33,MATCH(G40,値リスト!$B$27:$B$33,0)),"") -> coagulate | I40: 金属光沢はあるが、非常に重く加工しにくい未精製の鉱石。 | J40: 鈍く重い光沢を放つこの鉱石は、採掘者の工具を次々と折り、精製を拒む頑固者だ。しかし砕いて粉末にし薬液に加えると、その重さが沈殿し他の浮遊する成分を引き寄せて「凝固」させる。ぶれることなく底に居座るその安定感は、薬全体の成分を落ち着かせる「安定」の薬効として、不安定な調合を地に足のついたものへと変える。 | K40: 採取 | L40: 8 | M40: 素材 | O40: 素材
A41: item_037 | B41: キリンノナミダ | C41: 鉱物 | D41: {=IFERROR(INDEX(値リスト!$A$3:$A$9,MATCH(C41,値リスト!$B$3:$B$9,0)),"")} -> mineral | E41: 解毒 | F41: =IFERROR(INDEX(値リスト!$A$14:$A$24,MATCH(E41,値リスト!$B$14:$B$24,0)),"") -> detox | G41: 中和 | H41: =IFERROR(INDEX(値リスト!$A$27:$A$33,MATCH(G41,値リスト!$B$27:$B$33,0)),"") -> neutralize | I41: 虹色の光沢を持つ珍しい樹脂の化石。毒性を打ち消す浄化の性質を持つ。 | J41: 伝説の獣が流した涙が固まったという、虹色の化石。その輝きは、万物の毒性を浄化する至高の「中和」の力を宿している。どれほど危険な素材を組み合わせたとしても、この石を最後に一粒加えるだけで、禍々しい反応は凪ぎ、清らかな聖薬へと生まれ変わる。 | K41: 採取 | L41: 8 | M41: 素材 | O41: 素材
...

Sheet ItemSpawns
A1: ItemSpawns（採取場所・時間帯・確率） ― 1行 ＝ itemId × 場所 × 時間帯
A2: itemId → Items シート参照 | B2: terrainId → Terrains シート参照 | C2: timeSlot 時間帯 ▼日本語で選択 | D2: timeSlot ※自動入力 | E2: spawnRate 出現確率 0.0 〜 1.0 | F2: quantity 採取数 省略可(=1) | G2: condition 追加条件 例: rain / winter | H2: 備考
A3: item_001 | B3: ter_leaflitter | C3: 夜 | D3: =IFERROR(INDEX(値リスト!$G$16:$G$21,MATCH(C3,値リスト!$H$16:$H$21,0)),"") -> night | E3: 0.65 | F3: 1 | H3: 落ち葉の下に群生
A4: item_001 | B4: ter_deadwood | C4: 夜 | D4: =IFERROR(INDEX(値リスト!$G$16:$G$21,MATCH(C4,値リスト!$H$16:$H$21,0)),"") -> night | E4: 0.5 | F4: 1
A5: item_001 | B5: ter_leaflitter | C5: 夜明け | D5: =IFERROR(INDEX(値リスト!$G$16:$G$21,MATCH(C5,値リスト!$H$16:$H$21,0)),"") -> dawn | E5: 0.35 | F5: 1
A6: item_001 | B6: ter_darkness | C6: 夜 | D6: =IFERROR(INDEX(値リスト!$G$16:$G$21,MATCH(C6,値リスト!$H$16:$H$21,0)),"") -> night | E6: 0.3 | F6: 1
A7: item_002 | B7: ter_grass | C7: 朝 | D7: =IFERROR(INDEX(値リスト!$G$16:$G$21,MATCH(C7,値リスト!$H$16:$H$21,0)),"") -> morning | E7: 0.55 | F7: 1
A8: item_002 | B8: ter_glade | C8: 朝 | D8: =IFERROR(INDEX(値リスト!$G$16:$G$21,MATCH(C8,値リスト!$H$16:$H$21,0)),"") -> morning | E8: 0.45 | F8: 1
A9: item_002 | B9: ter_grass | C9: 昼 | D9: =IFERROR(INDEX(値リスト!$G$16:$G$21,MATCH(C9,値リスト!$H$16:$H$21,0)),"") -> noon | E9: 0.2 | F9: 1 | G9: 雨
A10: item_003 | B10: ter_leaflitter | C10: 夜 | D10: =IFERROR(INDEX(値リスト!$G$16:$G$21,MATCH(C10,値リスト!$H$16:$H$21,0)),"") -> night | E10: 0.18 | F10: 1 | H10: 希少：ニガタケに紛れる
A11: item_003 | B11: ter_deadwood | C11: 深夜 | D11: =IFERROR(INDEX(値リスト!$G$16:$G$21,MATCH(C11,値リスト!$H$16:$H$21,0)),"") -> midnight | E11: 0.12 | F11: 1
A12: item_004 | B12: ter_peat | C12: 夜 | D12: =IFERROR(INDEX(値リスト!$G$16:$G$21,MATCH(C12,値リスト!$H$16:$H$21,0)),"") -> night | E12: 0.45 | F12: 1 | H12: 泥炭層から掘る
A13: item_004 | B13: ter_mud | C13: 夜明け | D13: =IFERROR(INDEX(値リスト!$G$16:$G$21,MATCH(C13,値リスト!$H$16:$H$21,0)),"") -> dawn | E13: 0.28 | F13: 1
A14: item_005 | B14: ter_deadwood | C14: 朝 | D14: =IFERROR(INDEX(値リスト!$G$16:$G$21,MATCH(C14,値リスト!$H$16:$H$21,0)),"") -> morning | E14: 0.6 | F14: 1 | H14: 腐った倒木に群生
A15: item_005 | B15: ter_deadwood | C15: 夜 | D15: =IFERROR(INDEX(値リスト!$G$16:$G$21,MATCH(C15,値リスト!$H$16:$H$21,0)),"") -> night | E15: 0.45 | F15: 1
A16: item_005 | B16: ter_snag | C16: 昼 | D16: =IFERROR(INDEX(値リスト!$G$16:$G$21,MATCH(C16,値リスト!$H$16:$H$21,0)),"") -> noon | E16: 0.35 | F16: 1
A17: item_006 | B17: ter_trunk | C17: 朝 | D17: =IFERROR(INDEX(値リスト!$G$16:$G$21,MATCH(C17,値リスト!$H$16:$H$21,0)),"") -> morning | E17: 0.5 | F17: 1 | H17: 針葉樹の根元
A18: item_006 | B18: ter_alpine | C18: 朝 | D18: =IFERROR(INDEX(値リスト!$G$16:$G$21,MATCH(C18,値リスト!$H$16:$H$21,0)),"") -> morning | E18: 0.3 | F18: 1
A19: item_007 | B19: ter_rock | C19: 昼 | D19: =IFERROR(INDEX(値リスト!$G$16:$G$21,MATCH(C19,値リスト!$H$16:$H$21,0)),"") -> noon | E19: 0.35 | F19: 1
A20: item_007 | B20: ter_stalactite | C20: 夜 | D20: =IFERROR(INDEX(値リスト!$G$16:$G$21,MATCH(C20,値リスト!$H$16:$H$21,0)),"") -> night | E20: 0.28 | F20: 1
A21: item_007 | B21: ter_reef | C21: 昼 | D21: =IFERROR(INDEX(値リスト!$G$16:$G$21,MATCH(C21,値リスト!$H$16:$H$21,0)),"") -> noon | E21: 0.22 | F21: 1
A22: item_008 | B22: ter_snag | C22: 深夜 | D22: =IFERROR(INDEX(値リスト!$G$16:$G$21,MATCH(C22,値リスト!$H$16:$H$21,0)),"") -> midnight | E22: 0.12 | F22: 1 | H22: 希少：他の菌に寄生
A23: item_008 | B23: ter_deadwood | C23: 夜 | D23: =IFERROR(INDEX(値リスト!$G$16:$G$21,MATCH(C23,値リスト!$H$16:$H$21,0)),"") -> night | E23: 0.09 | F23: 1
A24: item_009 | B24: ter_sand | C24: 昼 | D24: =IFERROR(INDEX(値リスト!$G$16:$G$21,MATCH(C24,値リスト!$H$16:$H$21,0)),"") -> noon | E24: 0.5 | F24: 1 | H24: 乾いた砂地
A25: item_009 | B25: ter_dune | C25: 午後 | D25: =IFERROR(INDEX(値リスト!$G$16:$G$21,MATCH(C25,値リスト!$H$16:$H$21,0)),"") -> afternoon | E25: 0.38 | F25: 1
A26: item_010 | B26: ter_leaflitter | C26: 午後 | D26: =IFERROR(INDEX(値リスト!$G$16:$G$21,MATCH(C26,値リスト!$H$16:$H$21,0)),"") -> afternoon | E26: 0.35 | F26: 1
A27: item_010 | B27: ter_alpine | C27: 朝 | D27: =IFERROR(INDEX(値リスト!$G$16:$G$21,MATCH(C27,値リスト!$H$16:$H$21,0)),"") -> morning | E27: 0.22 | F27: 1
A28: item_011 | B28: ter_stagnant | C28: 深夜 | D28: =IFERROR(INDEX(値リスト!$G$16:$G$21,MATCH(C28,値リスト!$H$16:$H$21,0)),"") -> midnight | E28: 0.3 | F28: 1 | H28: 腐臭のする水際
A29: item_011 | B29: ter_ruinhouse | C29: 夜 | D29: =IFERROR(INDEX(値リスト!$G$16:$G$21,MATCH(C29,値リスト!$H$16:$H$21,0)),"") -> night | E29: 0.2 | F29: 1
A30: item_012 | B30: ter_trunk | C30: 昼 | D30: =IFERROR(INDEX(値リスト!$G$16:$G$21,MATCH(C30,値リスト!$H$16:$H$21,0)),"") -> noon | E30: 0.4 | F30: 1 | H30: 松の根元の地中
A31: item_012 | B31: ter_leaflitter | C31: 昼 | D31: =IFERROR(INDEX(値リスト!$G$16:$G$21,MATCH(C31,値リスト!$H$16:$H$21,0)),"") -> noon | E31: 0.25 | F31: 1
A32: item_013 | B32: ter_snowfield | C32: 夜明け | D32: =IFERROR(INDEX(値リスト!$G$16:$G$21,MATCH(C32,値リスト!$H$16:$H$21,0)),"") -> dawn | E32: 0.16 | F32: 1 | H32: 希少：雪の際の岩肌
A33: item_013 | B33: ter_ledge | C33: 深夜 | D33: =IFERROR(INDEX(値リスト!$G$16:$G$21,MATCH(C33,値リスト!$H$16:$H$21,0)),"") -> midnight | E33: 0.11 | F33: 1
A34: item_014 | B34: ter_fumarole | C34: 昼 | D34: =IFERROR(INDEX(値リスト!$G$16:$G$21,MATCH(C34,値リスト!$H$16:$H$21,0)),"") -> noon | E34: 0.06 | F34: 1 | H34: 極稀：噴気孔の縁
A35: item_014 | B35: ter_fumarole | C35: 深夜 | D35: =IFERROR(INDEX(値リスト!$G$16:$G$21,MATCH(C35,値リスト!$H$16:$H$21,0)),"") -> midnight | E35: 0.03 | F35: 1 | G35: 満月 | H35: 極稀：満月の夜のみ
A36: item_015 | B36: ter_shallow | C36: 朝 | D36: =IFERROR(INDEX(値リスト!$G$16:$G$21,MATCH(C36,値リスト!$H$16:$H$21,0)),"") -> morning | E36: 0.6 | F36: 1 | H36: 水際に群生
A37: item_015 | B37: ter_reed | C37: 昼 | D37: =IFERROR(INDEX(値リスト!$G$16:$G$21,MATCH(C37,値リスト!$H$16:$H$21,0)),"") -> noon | E37: 0.45 | F37: 1
A38: item_015 | B38: ter_tidepool | C38: 朝 | D38: =IFERROR(INDEX(値リスト!$G$16:$G$21,MATCH(C38,値リスト!$H$16:$H$21,0)),"") -> morning | E38: 0.25 | F38: 1
A39: item_016 | B39: ter_grass | C39: 朝 | D39: =IFERROR(INDEX(値リスト!$G$16:$G$21,MATCH(C39,値リスト!$H$16:$H$21,0)),"") -> morning | E39: 0.55 | F39: 1
A40: item_016 | B40: ter_shrub | C40: 午後 | D40: =IFERROR(INDEX(値リスト!$G$16:$G$21,MATCH(C40,値リスト!$H$16:$H$21,0)),"") -> afternoon | E40: 0.45 | F40: 1
...

Sheet Recipes
A1: Recipes（data_recipes.js） ― 1行 ＝ 1素材条件 同じ result を複数行で列挙
A2: result 生成物名 （複数行に同名OK） | B2: No 素材 番号 | C2: checkType 判定タイプ ▼日本語で選択 | D2: checkType ※自動入力 | E2: value 判定値 IDまたは値を入力 | F2: checkType2 判定タイプ2 ▼日本語で選択（AND条件・省略可） | G2: checkType2 ※自動入力 | H2: value2 判定値2 IDまたは値を入力（AND条件・省略可） | I2: processId 加工法 ▼日本語で選択 | J2: processId ※自動入力 | K2: quantity 必要数 省略可(=1) | L2: 備考 代替・バランスメモ | M2: 実装済? ✔を入力 | N2: 容器 薬瓶 / ガラス瓶 / なし
A3: 加速の秘薬 | B3: 1 | C3: 特定アイテムID | D3: =IFERROR(INDEX(値リスト!$G$25:$G$29,MATCH(C3,値リスト!$H$25:$H$29,0)),"") -> itemId | E3: item_003 | I3: すりつぶす | J3: =IFERROR(INDEX(値リスト!$G$3:$G$11,MATCH(I3,値リスト!$H$3:$H$11,0)),"") -> grind | K3: 1 | L3: ニガハシリダケ限定 | M3: ✔ | N3: 薬瓶
A4: 加速の秘薬 | B4: 2 | C4: カテゴリID | D4: =IFERROR(INDEX(値リスト!$G$25:$G$29,MATCH(C4,値リスト!$H$25:$H$29,0)),"") -> categoryId | E4: liquid | I4: 煮る | J4: =IFERROR(INDEX(値リスト!$G$3:$G$11,MATCH(I4,値リスト!$H$3:$H$11,0)),"") -> boil | K4: 1 | L4: 水系ならなんでもOK | M4: ✔ | N4: 薬瓶
A6: 汎用毒消し | B6: 1 | C6: 薬効ID | D6: =IFERROR(INDEX(値リスト!$G$25:$G$29,MATCH(C6,値リスト!$H$25:$H$29,0)),"") -> effectId | E6: detox | I6: 煮る | J6: =IFERROR(INDEX(値リスト!$G$3:$G$11,MATCH(I6,値リスト!$H$3:$H$11,0)),"") -> boil | K6: 1 | L6: 解毒効果を持つ素材 | M6: ✔ | N6: 薬瓶
A7: 汎用毒消し | B7: 2 | C7: 調合時効果ID | D7: =IFERROR(INDEX(値リスト!$G$25:$G$29,MATCH(C7,値リスト!$H$25:$H$29,0)),"") -> reactionId | E7: neutralize | I7: そのまま | J7: =IFERROR(INDEX(値リスト!$G$3:$G$11,MATCH(I7,値リスト!$H$3:$H$11,0)),"") -> raw | K7: 1 | L7: 中和の性質を持つ素材 | M7: ✔ | N7: 薬瓶
A9: 蒸留水 | B9: 1 | C9: カテゴリID | D9: =IFERROR(INDEX(値リスト!$G$25:$G$29,MATCH(C9,値リスト!$H$25:$H$29,0)),"") -> categoryId | E9: liquid | I9: 蒸留 | J9: =IFERROR(INDEX(値リスト!$G$3:$G$11,MATCH(I9,値リスト!$H$3:$H$11,0)),"") -> distill | K9: 1 | L9: 水質素材ならなんでもOK | N9: 薬瓶
A11: 純化水 | B11: 1 | C11: 特定アイテムID | D11: =IFERROR(INDEX(値リスト!$G$25:$G$29,MATCH(C11,値リスト!$H$25:$H$29,0)),"") -> itemId | E11: item_059 | I11: そのまま | J11: =IFERROR(INDEX(値リスト!$G$3:$G$11,MATCH(I11,値リスト!$H$3:$H$11,0)),"") -> raw | K11: 1 | L11: ベース：蒸留水 | N11: 薬瓶
A12: 純化水 | B12: 2 | C12: 調合時効果ID | D12: =IFERROR(INDEX(値リスト!$G$25:$G$29,MATCH(C12,値リスト!$H$25:$H$29,0)),"") -> reactionId | E12: separate | I12: 溶かす | J12: =IFERROR(INDEX(値リスト!$G$3:$G$11,MATCH(I12,値リスト!$H$3:$H$11,0)),"") -> dissolve | K12: 1 | L12: 分離特性の素材を溶かす（例：深層の塩水・白砂晶・墨痕石） | N12: 薬瓶
A14: 超純水 | B14: 1 | C14: 特定アイテムID | D14: =IFERROR(INDEX(値リスト!$G$25:$G$29,MATCH(C14,値リスト!$H$25:$H$29,0)),"") -> itemId | E14: item_059 | I14: 蒸留 | J14: =IFERROR(INDEX(値リスト!$G$3:$G$11,MATCH(I14,値リスト!$H$3:$H$11,0)),"") -> distill | K14: 1 | L14: 蒸留水をベースに蒸留 | N14: 薬瓶
A15: 超純水 | B15: 2 | C15: 特定アイテムID | D15: =IFERROR(INDEX(値リスト!$G$25:$G$29,MATCH(C15,値リスト!$H$25:$H$29,0)),"") -> itemId | E15: item_060 | I15: そのまま | J15: =IFERROR(INDEX(値リスト!$G$3:$G$11,MATCH(I15,値リスト!$H$3:$H$11,0)),"") -> raw | K15: 1 | L15: 純化水を加えて二重浄化 | N15: 薬瓶
A17: 凝固薬 | B17: 1 | C17: カテゴリID | D17: =IFERROR(INDEX(値リスト!$G$25:$G$29,MATCH(C17,値リスト!$H$25:$H$29,0)),"") -> categoryId | E17: liquid | I17: 煮る | J17: =IFERROR(INDEX(値リスト!$G$3:$G$11,MATCH(I17,値リスト!$H$3:$H$11,0)),"") -> boil | K17: 1 | L17: 水質ベース | N17: 薬瓶
A18: 凝固薬 | B18: 2 | C18: 調合時効果ID | D18: =IFERROR(INDEX(値リスト!$G$25:$G$29,MATCH(C18,値リスト!$H$25:$H$29,0)),"") -> reactionId | E18: coagulate | I18: そのまま | J18: =IFERROR(INDEX(値リスト!$G$3:$G$11,MATCH(I18,値リスト!$H$3:$H$11,0)),"") -> raw | K18: 1 | L18: 凝固特性の素材を加える（例：鍾乳洞の滴り・樹皮を伝う雨水） | N18: 薬瓶
A20: 浸透溶媒 | B20: 1 | C20: 調合時効果ID | D20: =IFERROR(INDEX(値リスト!$G$25:$G$29,MATCH(C20,値リスト!$H$25:$H$29,0)),"") -> reactionId | E20: permeate | I20: 蒸留 | J20: =IFERROR(INDEX(値リスト!$G$3:$G$11,MATCH(I20,値リスト!$H$3:$H$11,0)),"") -> distill | K20: 1 | L20: 浸透特性の水質を蒸留（例：草木の朝露・灰から取った灰汁） | N20: 薬瓶
A21: 浸透溶媒 | B21: 2 | C21: カテゴリID | D21: =IFERROR(INDEX(値リスト!$G$25:$G$29,MATCH(C21,値リスト!$H$25:$H$29,0)),"") -> categoryId | E21: flora | I21: 溶かす | J21: =IFERROR(INDEX(値リスト!$G$3:$G$11,MATCH(I21,値リスト!$H$3:$H$11,0)),"") -> dissolve | K21: 1 | L21: 植物素材を溶かし込む | N21: 薬瓶
A23: 強発酵液 | B23: 1 | C23: 特定アイテムID | D23: =IFERROR(INDEX(値リスト!$G$25:$G$29,MATCH(C23,値リスト!$H$25:$H$29,0)),"") -> itemId | E23: item_039 | I23: 発酵させる | J23: =IFERROR(INDEX(値リスト!$G$3:$G$11,MATCH(I23,値リスト!$H$3:$H$11,0)),"") -> ferment | K23: 1 | L23: 雨溜まりの泥水を発酵 | N23: 薬瓶
A24: 強発酵液 | B24: 2 | C24: カテゴリID | D24: =IFERROR(INDEX(値リスト!$G$25:$G$29,MATCH(C24,値リスト!$H$25:$H$29,0)),"") -> categoryId | E24: fungi | I24: そのまま | J24: =IFERROR(INDEX(値リスト!$G$3:$G$11,MATCH(I24,値リスト!$H$3:$H$11,0)),"") -> raw | K24: 1 | L24: 菌類を加えて発酵を促進 | N24: 薬瓶
A26: 保存溶液 | B26: 1 | C26: 調合時効果ID | D26: =IFERROR(INDEX(値リスト!$G$25:$G$29,MATCH(C26,値リスト!$H$25:$H$29,0)),"") -> reactionId | E26: preserve | I26: 煮る | J26: =IFERROR(INDEX(値リスト!$G$3:$G$11,MATCH(I26,値リスト!$H$3:$H$11,0)),"") -> boil | K26: 1 | L26: 保存特性の水質を煮る（例：鉄渋の湧き水・古井戸の溜まり水） | N26: 薬瓶
A27: 保存溶液 | B27: 2 | C27: カテゴリID | D27: =IFERROR(INDEX(値リスト!$G$25:$G$29,MATCH(C27,値リスト!$H$25:$H$29,0)),"") -> categoryId | E27: mineral | I27: 溶かす | J27: =IFERROR(INDEX(値リスト!$G$3:$G$11,MATCH(I27,値リスト!$H$3:$H$11,0)),"") -> dissolve | K27: 1 | L27: 鉱物素材を溶かし安定性を高める | N27: 薬瓶
A29: 野草の傷薬 | B29: 1 | C29: カテゴリID | D29: =IFERROR(INDEX(値リスト!$G$25:$G$29,MATCH(C29,値リスト!$H$25:$H$29,0)),"") -> categoryId | E29: flora | F29: 薬効ID | G29: =IFERROR(INDEX(値リスト!$G$25:$G$29,MATCH(F29,値リスト!$H$25:$H$29,0)),"") -> effectId | H29: healing | I29: 煮る | J29: =IFERROR(INDEX(値リスト!$G$3:$G$11,MATCH(I29,値リスト!$H$3:$H$11,0)),"") -> boil | K29: 1 | L29: 植物かつ治癒の素材（イバラアザミ・ハッカガヤ・ニガヨモギモドキなど） | N29: 薬瓶
A30: 野草の傷薬 | B30: 2 | C30: カテゴリID | D30: =IFERROR(INDEX(値リスト!$G$25:$G$29,MATCH(C30,値リスト!$H$25:$H$29,0)),"") -> categoryId | E30: liquid | I30: そのまま | J30: =IFERROR(INDEX(値リスト!$G$3:$G$11,MATCH(I30,値リスト!$H$3:$H$11,0)),"") -> raw | K30: 1 | L30: 水でのばす | N30: 薬瓶
A35: 鎮静の丸薬 | B35: 1 | C35: 薬効ID | D35: =IFERROR(INDEX(値リスト!$G$25:$G$29,MATCH(C35,値リスト!$H$25:$H$29,0)),"") -> effectId | E35: sedation | I35: 煮る | J35: =IFERROR(INDEX(値リスト!$G$3:$G$11,MATCH(I35,値リスト!$H$3:$H$11,0)),"") -> boil | K35: 1 | L35: 鎮静効果の素材（青泥石・氷晶石モドキ・オオツユグサなど） | N35: なし
A36: 鎮静の丸薬 | B36: 2 | C36: 調合時効果ID | D36: =IFERROR(INDEX(値リスト!$G$25:$G$29,MATCH(C36,値リスト!$H$25:$H$29,0)),"") -> reactionId | E36: coagulate | I36: そのまま | J36: =IFERROR(INDEX(値リスト!$G$3:$G$11,MATCH(I36,値リスト!$H$3:$H$11,0)),"") -> raw | K36: 1 | L36: 凝固素材で丸薬に固める | N36: なし
A37: 鎮静の丸薬 | B37: 3 | C37: カテゴリID | D37: =IFERROR(INDEX(値リスト!$G$25:$G$29,MATCH(C37,値リスト!$H$25:$H$29,0)),"") -> categoryId | E37: liquid | I37: そのまま | J37: =IFERROR(INDEX(値リスト!$G$3:$G$11,MATCH(I37,値リスト!$H$3:$H$11,0)),"") -> raw | K37: 1 | L37: 溶媒 | N37: なし
A39: 目覚め薬 | B39: 1 | C39: 特定アイテムID | D39: =IFERROR(INDEX(値リスト!$G$25:$G$29,MATCH(C39,値リスト!$H$25:$H$29,0)),"") -> itemId | E39: item_049 | I39: すりつぶす | J39: =IFERROR(INDEX(値リスト!$G$3:$G$11,MATCH(I39,値リスト!$H$3:$H$11,0)),"") -> grind | K39: 1 | L39: トゲネズミの抜け殻（固定） | N39: なし
A40: 目覚め薬 | B40: 2 | C40: 調合時効果ID | D40: =IFERROR(INDEX(値リスト!$G$25:$G$29,MATCH(C40,値リスト!$H$25:$H$29,0)),"") -> reactionId | E40: volatile | I40: そのまま | J40: =IFERROR(INDEX(値リスト!$G$3:$G$11,MATCH(I40,値リスト!$H$3:$H$11,0)),"") -> raw | K40: 1 | L40: 揮発素材で吸引薬に（カサカサ草・ミズススリの浮き袋など） | N40: なし
A42: 滋養の煎じ薬 | B42: 1 | C42: 薬効ID | D42: =IFERROR(INDEX(値リスト!$G$25:$G$29,MATCH(C42,値リスト!$H$25:$H$29,0)),"") -> effectId | E42: tonic | I42: 煮る | J42: =IFERROR(INDEX(値リスト!$G$3:$G$11,MATCH(I42,値リスト!$H$3:$H$11,0)),"") -> boil | K42: 1 | L42: 滋養強壮の素材（ドロワリタケ・ツボミカズラ・ネバリダイコンなど） | N42: 薬瓶
A43: 滋養の煎じ薬 | B43: 2 | C43: 調合時効果ID | D43: =IFERROR(INDEX(値リスト!$G$25:$G$29,MATCH(C43,値リスト!$H$25:$H$29,0)),"") -> reactionId | E43: permeate | I43: そのまま | J43: =IFERROR(INDEX(値リスト!$G$3:$G$11,MATCH(I43,値リスト!$H$3:$H$11,0)),"") -> raw | K43: 1 | L43: 浸透素材で体の芯まで | N43: 薬瓶
A44: 滋養の煎じ薬 | B44: 3 | C44: 特定アイテムID | D44: =IFERROR(INDEX(値リスト!$G$25:$G$29,MATCH(C44,値リスト!$H$25:$H$29,0)),"") -> itemId | E44: item_041 | I44: そのまま | J44: =IFERROR(INDEX(値リスト!$G$3:$G$11,MATCH(I44,値リスト!$H$3:$H$11,0)),"") -> raw | K44: 1 | L44: 鉄渋の湧き水（固定）：効能を定着させる | N44: 薬瓶
A46: 煙の護符 | B46: 1 | C46: 薬効ID | D46: =IFERROR(INDEX(値リスト!$G$25:$G$29,MATCH(C46,値リスト!$H$25:$H$29,0)),"") -> effectId | E46: insulation | I46: 乾燥させる | J46: =IFERROR(INDEX(値リスト!$G$3:$G$11,MATCH(I46,値リスト!$H$3:$H$11,0)),"") -> dry | K46: 1 | L46: 防護効果の素材（ユウヒダケ・イワノボリツル・雲母片岩など） | N46: なし
A47: 煙の護符 | B47: 2 | C47: 調合時効果ID | D47: =IFERROR(INDEX(値リスト!$G$25:$G$29,MATCH(C47,値リスト!$H$25:$H$29,0)),"") -> reactionId | E47: volatile | I47: そのまま | J47: =IFERROR(INDEX(値リスト!$G$3:$G$11,MATCH(I47,値リスト!$H$3:$H$11,0)),"") -> raw | K47: 1 | L47: 揮発素材で煙に変える | N47: なし
A48: 煙の護符 | B48: 3 | C48: 特定アイテムID | D48: =IFERROR(INDEX(値リスト!$G$25:$G$29,MATCH(C48,値リスト!$H$25:$H$29,0)),"") -> itemId | E48: item_017 | I48: そのまま | J48: =IFERROR(INDEX(値リスト!$G$3:$G$11,MATCH(I48,値リスト!$H$3:$H$11,0)),"") -> raw | K48: 1 | L48: カサカサ草（固定）：着火補助 | N48: なし
... A119: 麹 | B119: 1 | C119: カテゴリID | D119: =IFERROR(INDEX(値リスト!$G$25:$G$29,MATCH(C119,値リスト!$H$25:$H$29,0)),"") -> categoryId | E119: fungi | I119: 発酵させる | J119: =IFERROR(INDEX(値リスト!$G$3:$G$11,MATCH(I119,値リスト!$H$3:$H$11,0)),"") -> ferment | K119: 1 | L119: 【T0】菌類を寝かせる | N119: なし
A121: 薬草粉 | B121: 1 | C121: カテゴリID | D121: =IFERROR(INDEX(値リスト!$G$25:$G$29,MATCH(C121,値リスト!$H$25:$H$29,0)),"") -> categoryId | E121: flora | F121: 薬効ID | G121: =IFERROR(INDEX(値リスト!$G$25:$G$29,MATCH(F121,値リスト!$H$25:$H$29,0)),"") -> effectId | H121: healing | I121: 乾燥させる | J121: =IFERROR(INDEX(値リスト!$G$3:$G$11,MATCH(I121,値リスト!$H$3:$H$11,0)),"") -> dry | K121: 1 | L121: 【T0】植物かつ治癒（イバラアザミ・ハッカガヤ・ニガヨモギモドキ） | N121: なし
A123: 灰汁液 | B123: 1 | C123: 特定アイテムID | D123: =IFERROR(INDEX(値リスト!$G$25:$G$29,MATCH(C123,値リスト!$H$25:$H$29,0)),"") -> itemId | E123: item_068 | I123: そのまま | J123: =IFERROR(INDEX(値リスト!$G$3:$G$11,MATCH(I123,値リスト!$H$3:$H$11,0)),"") -> raw | K123: 1 | L123: 【T1】 | N123: 薬瓶
A124: 灰汁液 | B124: 2 | C124: カテゴリID | D124: =IFERROR(INDEX(値リスト!$G$25:$G$29,MATCH(C124,値リスト!$H$25:$H$29,0)),"") -> categoryId | E124: liquid | I124: 煮る | J124: =IFERROR(INDEX(値リスト!$G$3:$G$11,MATCH(I124,値リスト!$H$3:$H$11,0)),"") -> boil | K124: 1 | L124: 水質で煮出す | N124: 薬瓶
A126: 獣脂 | B126: 1 | C126: カテゴリID | D126: =IFERROR(INDEX(値リスト!$G$25:$G$29,MATCH(C126,値リスト!$H$25:$H$29,0)),"") -> categoryId | E126: creature | F126: 調合時効果ID | G126: =IFERROR(INDEX(値リスト!$G$25:$G$29,MATCH(F126,値リスト!$H$25:$H$29,0)),"") -> reactionId | H126: preserve | I126: 煮る | J126: =IFERROR(INDEX(値リスト!$G$3:$G$11,MATCH(I126,値リスト!$H$3:$H$11,0)),"") -> boil | K126: 1 | L126: 【T1】保存特性の動物性素材 | N126: 薬瓶
A127: 獣脂 | B127: 2 | C127: カテゴリID | D127: =IFERROR(INDEX(値リスト!$G$25:$G$29,MATCH(C127,値リスト!$H$25:$H$29,0)),"") -> categoryId | E127: liquid | I127: そのまま | J127: =IFERROR(INDEX(値リスト!$G$3:$G$11,MATCH(I127,値リスト!$H$3:$H$11,0)),"") -> raw | K127: 1 | L127: 水でのばす | N127: 薬瓶
A129: 膠 | B129: 1 | C129: 特定アイテムID | D129: =IFERROR(INDEX(値リスト!$G$25:$G$29,MATCH(C129,値リスト!$H$25:$H$29,0)),"") -> itemId | E129: item_054 | I129: 煮る | J129: =IFERROR(INDEX(値リスト!$G$3:$G$11,MATCH(I129,値リスト!$H$3:$H$11,0)),"") -> boil | K129: 1 | L129: 【T1】ツギハギヘビの抜け殻を煮詰める | N129: なし
A130: 膠 | B130: 2 | C130: 特定アイテムID | D130: =IFERROR(INDEX(値リスト!$G$25:$G$29,MATCH(C130,値リスト!$H$25:$H$29,0)),"") -> itemId | E130: item_076 | I130: そのまま | J130: =IFERROR(INDEX(値リスト!$G$3:$G$11,MATCH(I130,値リスト!$H$3:$H$11,0)),"") -> raw | K130: 1 | L130: 灰汁で分解を助ける | N130: なし
...

Sheet RecipeHints
A1: RecipeHints（調合のヒント） ― 1行＝1枚の紙片。同じ result に何枚あってもよい
A2: result 対象レシピ名 | B2: hintNo 同一レシピ内の 通し番号 | C2: source 出所 ▼ | D2: title 紙片の見出し | E2: text 本文 | F2: reliability 確度 ▼ | G2: unlock 解明すると手に入る レシピ名を書く 空欄＝最初から所持 | H2: 備考
A3: 蒸留水 | B3: 1 | C3: 手書きメモ | D3: 湯気の雫 | E3: 祖母はまず必ず水を火にかけた。鍋に蓋をして、伝ってくる雫だけを別の器に集める。水はどこの水でもいい、濁っていても構わないと言っていた。「これをやらずに薬を作る奴は、泥水で顔を洗うようなものだ」 | F3: 確か | H3: 深さ0：主人公の回想
A4: 木灰 | B4: 1 | C4: 手書きメモ | D4: 竈の始末 | E4: 燃やしたあとの灰を、祖母は決して捨てなかった。とくに、乾いた地面に生える一年中枯れたような茶色い草はよく燃えると言って、いつも引き抜いてきた。 | F4: 確か | H4: 深さ0：主人公の回想
A5: 鉱石粉 | B5: 1 | C5: 手書きメモ | D5: 石臼の音 | E5: 石臼の重い音は、子供の頃の家の音だった。河原でも岩場でも、拾ってきた石を根気よく挽いて粉にしてしまう。石なら何でもよかったらしい。 | F5: 確か | H5: 深さ0：主人公の回想
A6: 骨炭 | B6: 1 | C6: 手書きメモ | D6: 黒くなるまで | E6: 獣や魚から採ったものを炉に入れて、真っ黒になるまで焼いていた。川で採れる鱗だったか、夜の草むらで拾った獣の皮だったか。何に使うのか聞いたら「臭いを吸わせるのさ」と答えた、気がする。 | F6: 曖昧 | H6: 深さ0：主人公の回想
A7: 麹 | B7: 1 | C7: 手書きメモ | D7: 桶を暗いところへ | E7: 茸を桶に入れて、暗い場所に置いておく。落ち葉の下から採ってきたありふれた茸で十分だと言っていた。数日で表に白い粉を吹く。あれが酒の元になる。 | F7: 確か | H7: 深さ0：主人公の回想
A8: 薬草粉 | B8: 1 | C8: 手書きメモ | D8: 生のまま挽くな | E8: 傷に効く草は、生のまま挽いてはいけない。必ず先に乾かす。朝の草むらで摘んだ棘だらけの草を、軒下に吊るしていた。「水気が残ると効きが逃げる」と言っていたと思う。 | F8: 曖昧 | H8: 深さ0：主人公の回想
A9: 精製塩 | B9: 1 | C9: 手書きメモ | D9: 煮ると苦くなる | E9: 潮だまりから汲んでくる、やけに塩辛い水。祖母はそれを火にかけず、天日に置いた。煮ると苦くなるのだと。待つのが仕事だと言われて、ひどく退屈だった。 | F9: 確か | H9: 深さ0：主人公の回想
A10: 硫黄華 | B10: 1 | C10: 手書きメモ | D10: 臭い湯の湯気 | E10: 湯の湧く土地まで、半日かけて水を汲みに行った。鼻を突く匂いのする水だ。持ち帰って蒸留にかけると、黄色い粉だけが残る。指でつまんで匂いを嗅がされた覚えがある。 | F10: 曖昧 | H10: 深さ0：主人公の回想
A11: 鉄粉 | B11: 1 | C11: 手書きメモ | D11: 錆びているほどよい | E11: 洞窟の岩肌を走る赤茶けた筋から、錆びた塊を掘ってくる。錆びているほどいいのだと言いながら挽いていた。廃屋の朽ちた金具からも同じものが採れた。 | F11: 確か | H11: 深さ0：主人公の回想
A12: 野草の傷薬 | B12: 1 | C12: 手書きメモ | D12: 祖母の手当て | E12: 膝を擦りむいて泣いていると、祖母は朝の草むらまで行って棘のある草を摘んできた。それを鍋で煮て、水でのばして塗ってくれた。青くさい匂いを今でも覚えている。 | F12: 曖昧 | H12: 深さ0：主人公の回想
A13: 凝固薬 | B13: 1 | C13: 手書きメモ | D13: 匙で掬える水 | E13: 水を煮ながら、粘るものを放り込んでいた。松の根元の地面を掘って出てくる、糸を引く茸だったと思う。冷めると鍋の中身が匙で掬えるようになっていて、覗き込んで驚いた。 | F13: 曖昧 | H13: 深さ0：主人公の回想
A14: 浸透溶媒 | B14: 1 | C14: 手書きメモ | D14: よく染みる水 | E14: 染み込む性質のものを先に蒸留して、そこへ草を溶かし込む。朝の草むらに生える、夜のうちに歩き回るという茸を使っていた気がする。これで作った薬はよく効くのだと、めずらしく自慢していた。 | F14: 曖昧 | H14: 深さ0：主人公の回想
... A30: 灯りの気 | B30: 1 | C30: 手書きメモ | D30: 熱くない灯り | E30: 洞窟の奥の暗がりでしか採れない、微かに光る牙。あれを蒸留して、揮発するものと合わせ、瓶に閉じ込める。青白く光るのに、瓶は少しも熱くならなかった。 | F30: 曖昧 | H30: 深さ0：主人公の回想
A31: 強発酵液 | B31: 2 | C31: もらったメモ | D31: 酒屋の親父から | E31: 雨の溜まった泥水を捨てるな。あれに茸を放り込んで寝かせておくと、とんでもなく強い酛になる。臭いは保証せんがね。 | F31: 確か | G31: 蒸留水 | H31: NPCから貰う想定
A32: 促進触媒 | B32: 1 | C32: 書籍のページの写し | D32: 『植物誌』第四巻より | E32: 沼地に生ずる黒き茸、その汁は反応の遅き物同士を強いて結びつく。これを酛に和すれば、成らざるものも成るという。 | F32: 確か | H32: 書物由来。やや古い言い回し
A33: 賢者アルドラスの霊薬 | B33: 1 | C33: 祖母の手書きの考察 | D33: 何度目かの失敗について | E33: また濁った。超純水も霊銀砂も揃えたのに、あと一歩が足りない。……思うに、私は「静かにすぎる」のかもしれない。この薬は思考を速める薬だ。ならば速める側の力を、もう一つ加えるべきではないか。 | F33: 誤りを含む | G33: 促進触媒 | H33: 祖母が解けなかったレシピ。結論は正しいが素材は特定できていない
A34: 眠り姫マルグレーテの微睡み香 | B34: 1 | C34: 祖母の手書きの考察 | D34: マルグレーテの香について | E34: 伝承では「百年の眠り」と言うが、香を焚いただけで人が百年眠るはずがない。おそらく体を冷やしている。冷たいものを、香に混ぜているのだ。 | F34: 曖昧 | G34: 鎮静水 | H34: 冷却晶への示唆
A35: 純化水 | B35: 1 | C35: 祖母のメモ | D35: 二度目の水 | E35: 蒸留した水に、分ける性のものを溶かす。深いところの塩水でも、砂浜の脆い結晶でも、洞窟の黒い石でもよい。濁りが底に沈む。ここまでやらねば上の薬は作れぬ。 | F35: 確か | H35: 深さ1：祖母の走り書き
A36: 促進触媒 | B36: 2 | C36: 祖母のメモ | D36: 急かす粉 | E36: 触媒の性を持つものを挽き、例の臭い液に入れる。沼の泥から出る黒く平たい茸がいちばん強い。これがあると、待っても起きぬ反応が起きる。 | F36: 確か | H36: 深さ1：祖母の走り書き
A37: 硬化の膏薬 | B37: 1 | C37: 祖母のメモ | D37: 締まる薬 | E37: 安定の効を溶かして、固め液を合わせる。溶岩の裂け目に生える角のような草。塗ると皮が締まる。深い傷には使うな。 | F37: 確か | H37: 深さ1：祖母の走り書き
A38: 鉄壁の護り薬 | B38: 1 | C38: 祖母のメモ | D38: 膜を張る | E38: 守りの効を溶かして固め液。岩棚の薄く剥がれる石でよい。皮の上に膜ができる。打たれる用。切られる時には間に合わぬ。 | F38: 確か | H38: 深さ1：祖母の走り書き
A39: 灰汁液 | B39: 1 | C39: 祖母のメモ | D39: 灰を煮る | E39: 灰を水で煮出すだけ。素手で触るな。前に指の皮が剥けた。 | F39: 確か | H39: 深さ1：祖母の走り書き
A40: 香油 | B40: 1 | C40: 祖母のメモ | D40: 匂いを移す | E40: 脂に、香りの強い草を溶かす。河原や朝の草むらの、踏むと涼しい匂いのするやつがよく移る。花でも試したが脂が濁った。 | F40: 確か | H40: 深さ1：祖母の走り書き
A41: 解毒エキス | B41: 1 | C41: 祖母のメモ | D41: 濃くする | E41: 解毒の効を煮て、染みる溶媒に取る。腐った倒木のぬめり茸でよい。そこらの毒ならこれで足りる。強い毒には効かぬ。 | F41: 確か | H41: 深さ1：祖母の走り書き
A42: 霊銀砂 | B42: 1 | C42: 祖母のメモ | D42: 銀の砂 | E42: 神秘の効を挽いて、石の粉と混ぜる。残雪の際の白い花がいちばん素直に混ざる。洞窟の光る牙は強すぎて手に負えぬ。 | F42: 確か | H42: 深さ1：祖母の走り書き
A43: 酒精 | B43: 1 | C43: 祖母のメモ | D43: 二度目の火 | E43: 臭い液を蒸留し、麹を足して整える。飲むためのものではない。傷を洗うため。じいさんには言うな。 | F43: 確か | H43: 深さ1：祖母の走り書き
A44: 苦灰塩 | B44: 1 | C44: 祖母のメモ | D44: 打ち消す粉 | E44: 灰に塩を溶かして練る。中和のものが手元に無い時の代わり。効きは落ちる。無いよりまし。 | F44: 確か | H44: 深さ1：祖母の走り書き
A45: 鎮静水 | B45: 1 | C45: 祖母のメモ | D45: 静める水 | E45: 鎮静の効を煮て、蒸留水に取る。夜明けの草むらで雫を溜めているやつ。濃くしすぎるな。前に隣の婆さんが半日起きなかった。 | F45: 確か | H45: 深さ1：祖母の走り書き
A46: 活性水 | B46: 1 | C46: 祖母のメモ | D46: 起こす水 | E46: 興奮の効を煮て、蒸留水に取る。溶岩の原で拾う火花の出る黒石でも、朝の草むらの茸でもよい。飲みすぎると手が震える。 | F46: 確か | H46: 深さ1：祖母の走り書き
... A106: 導きの銅線 | B106: 1 | C106: 書籍のページの写し | D106: 『鏡と光について』伝導の条 | E106: 銅の線に銀の砂を溶き入れ、三度清めたる水にて洗う。力の通り道となる。端から端まで、滞りなく。……何を通すのかは、記されていない。 | F106: 曖昧 | H106: 深さ2〜3
A107: 巫女セレネの霊視香 | B107: 1 | C107: 祖母の手書きの考察 | D107: 煙が濁る | E107: 神秘のものを干して、揮発するものを焼く。ここまでは間違いない。だが煙が濁る。何度やっても濁る。灰を下敷きにしても駄目だった。……もう一つ、濁りを吸うものが要るのではないか。黒く焼いたものは匂いを吸う。ならば濁りも吸うのではないか。灰と炭を両方入れるなど聞いたことがないが、他に思いつかぬ。 | F107: 曖昧 | G107: 骨炭 | H107: 人名：祖母が解けなかった調合
A108: 灯守ヨナの常夜灯 | B108: 1 | C108: 祖母の手書きの考察 | D108: 光が逃げる | E108: 洞窟の光る牙。あれは確かに光る。だが取り出して三日で光を失う。逃げるのだ。保つ性のものを溶かして留めてみたが、それでも半月しか持たぬ。……包むものが足りぬ。油で封じ、水で濁りを落とせば、あるいは。灯守の一族が代々守ったというのは、この封じ方のことではないか。 | F108: 曖昧 | G108: 硬化油 | H108: 人名：祖母が解けなかった調合
A109: 風読みフィオナの軟膏 | B109: 1 | C109: 祖母の手書きの考察 | D109: 二十年止まっている | E109: 浮く性質を持つものは確かにある。川の虫の浮き袋、蛾の粉。だが煮ると効きが飛ぶ。言葉の綾ではない。本当に軽くなって鍋から出ていってしまう。……脂で押さえるべきなのだろう。重いもので蓋をする。だが、それでは軽くならぬのではないか。この矛盾で二十年止まっている。 | F109: 曖昧 | G109: 促進触媒 | H109: 人名：祖母が解けなかった調合
A110: 魔女レウィシアの秘薬 | B110: 1 | C110: 祖母の手書きの考察 | D110: どちらかが負ける | E110: 癒しと神秘。この二つを一つの器に入れると、必ずどちらかが負ける。癒しが勝てばただの傷薬、神秘が勝てば何にもならぬ水。……間を取り持つものが要る。銀の砂か、急かす粉か、あるいは両方か。器は三度清めた水でなければ、どちらも溶けきらぬ。ここまで書いて、材料が揃わぬことに気付く。私の代では無理だ。 | F110: 曖昧 | G110: 超純水 | H110: 人名：祖母が解けなかった調合
A111: 錬金王オルドリンの黄金水 | B111: 1 | C111: 祖母の手書きの考察 | D111: 元に戻ってしまう | E111: 卑しい金属が貴い金属に変わるという。信じてはいない。だが変わることそのものは起きる。鉄の粉を三度清めた水に溶かし、黄の粉を添えると、確かに色が変わった。……そこで止まる。変わったものが、すぐ元に戻る。変化を留めるものが要る。安定の効か。私は錬金術師ではない、薬屋だ。だが気になって仕方がない。 | F111: 曖昧 | G111: 超純水 | H111: 人名：祖母が解けなかった調合
A112: 死神ヴェルナの一滴 | B112: 1 | C112: 祖母の手書きの考察 | D112: 作らなかった | E112: 書き残すべきか迷った。だが、知らぬまま作ってしまう者が出るより、知って避ける方がよい。……毒の濃汁をさらに蒸せば、毒だけが残る。黒炭で臭いを消し、清めた水で色を消せば、水と見分けがつかぬ。急かすものを入れれば、飲んだ者は座る間もない。ここまで分かって、私は作らなかった。作れなかったのではない。作らなかった。 | F112: 確か | G112: 猛毒エキス | H112: 人名：祖母が解けなかった調合
A113: 聖女アルテアの祝福水 | B113: 1 | C113: 祖母の手書きの考察 | D113: 塩の意味 | E113: 傷も病も退けたという。奇跡ではあるまい。癒しの核を蒸して取り、三度清めた水に落とす。ここまでは私にもできる。……足りぬのは清めだ。銀の砂と、神秘のもの、それから塩。塩を入れる意味が分からぬまま、伝承はそう言っている。分からぬものを分からぬまま書いておく。いつか分かる者がいるかもしれぬ。 | F113: 曖昧 | G113: 超純水 | H113: 人名：祖母が解けなかった調合
A114: 隠者ガラハの不老酒 | B114: 1 | C114: 祖母の手書きの考察 | D114: 百年を縮める | E114: 百年寝かせたという。嘘だ。百年も生きた者がどこにいる。……だが百年ぶんの熟成を早めることならできるかもしれぬ。臭い液と急かす粉、この二つは時を縮める。滋養のものを発酵させ、酒精を足し、銀の砂で留める。若返るとは思わぬ。だが飲んだ者が若く見えるくらいのことは、あるかもしれぬ。 | F114: 曖昧 | G114: 酒精 | H114: 人名：祖母が解けなかった調合
...
