Workbook

Sheet 値リスト
A1: categoryId | G1: processId
A2: ID | B2: 名前 | C2: icon | D2: 説明 | G2: ID | H2: 説明 | I2: 属性 | J2: 効果
A3: flora | B3: 植物 | C3: 🌿 | D3: 葉、花、茎など。調合の基本素材 | G3: grind | H3: すりつぶす | I3: 土属性強化 | J3: 反応性強化
A4: fungi | B4: 菌類 | C4: 🍄 | D4: キノコやカビ。特殊な変化をもたらす | G4: boil | H4: 煮る | I4: 水＋火属性強化 | J4: 融解
A5: liquid | B5: 水質 | C5: 🧪 | D5: 湧き水や朝露。液体ベース素材 | G5: dry | H5: 乾燥させる | I5: 風属性強化 | J5: 強化
A6: mineral | B6: 鉱物 | C6: 🪨 | D6: 石、塩、泥など。無機物素材 | G6: raw | H6: そのまま | I6: 鮮度アップ | J6: 鮮度
A7: creature | B7: 動物性 | C7: 🪶 | D7: 羽根や抜け殻、牙など | G7: ferment | H7: 発酵させる | I7: 無属性化 | J7: 変質
A8: relics | B8: 遺物 | C8: 🏺 | D8: 釘やコイン、ガラス瓶などの人工物 | G8: burn | H8: 焼く | I8: 火属性強化 | J8: 無毒化
A9: processed | B9: 加工品 | C9: 🫙 | D9: 調合の中間素材や二次的素材 | G9: freeze | H9: 凍らせる | I9: 郡属性強化 | J9: 保存
G10: dissolve | H10: 溶かす | I10: 水属性強化 | J10: 融解
G11: distill | H11: 蒸留 | I11: 無属性化 | J11: 純化
A12: effectId（薬効）
A13: ID | B13: 名前 | C13: icon | D13: 説明
A14: healing | B14: 治癒 | C14: 🩹 | D14: 傷口を塞ぎ体力を回復 | G14: timeSlot（例）
A15: detox | B15: 解毒 | C15: 🧪 | D15: 体内の毒素を中和 | G15: ID | H15: 説明
A16: tonic | B16: 滋養強壮 | C16: 🍗 | D16: 肉体の疲れを取り活力を | G16: dawn | H16: 夜明け
A17: stimulation | B17: 興奮 | C17: ⚡ | D17: 集中力・反応速度を一時UP | G17: morning | H17: 朝
A18: sedation | B18: 鎮静 | C18: 💤 | D18: 昂った精神を落ち着かせる | G18: noon | H18: 昼
A19: stable | B19: 安定 | C19: ⚪ | D19: 成分を安定させる | G19: afternoon | H19: 午後
A20: levitation | B20: 浮遊 | C20: 🎈 | D20: 重力の影響を中和する | G20: night | H20: 夜
A21: mystic | B21: 神秘 | C21: ☄️ | D21: 魔力回路を一時的に拡張 | G21: midnight | H21: 深夜
A22: insulation | B22: 防護 | C22: 🛡️ | D22: 属性ダメージを軽減
A23: poison | B23: 猛毒 | C23: 💀 | D23: 生命活動を停止させる | G23: checkType
A24: none | B24: なし | C24: ⚪ | D24: 特筆すべき薬効なし | G24: ID | H24: 説明
A25: reactionId（調合時の効果） | G25: itemId | H25: 特定アイテムID
A26: ID | B26: 表示名 | C26: 説明 | G26: categoryId | H26: カテゴリID
A27: coagulate | B27: 凝固 | C27: 液体や素材を固める。形状を保つのに使う | G27: effectId | H27: 薬効ID
A28: preserve | B28: 保存 | C28: 素材の鮮度や効果を長期間維持する | G28: reactionId | H28: 調合時効果ID
A29: separate | B29: 分離 | C29: 混合物から特定の成分を取り出す | G29: elementId | H29: 属性ID
A30: volatile | B30: 揮発 | C30: 成分を気化させる。気体素材の生成に
A31: permeate | B31: 浸透 | C31: 他の素材や対象に成分を染み込ませる
A32: catalyst | B32: 触媒 | C32: 他の反応を促進する。自身は変化しない
A33: neutralize | B33: 中和 | C33: 酸・毒・属性などの効果を打ち消す
A36: 【色の凡例】
A37: ▼ 日本語で選択入力する列
A38: 🔵 英語IDが自動表示される列（編集不要）

Sheet Items
A1: Items（data_items.js） ― 1行 ＝ 1アイテム
A2: id 例: item_001 | B2: name 日本語名 | C2: categoryId ▼日本語で選択 | D2: categoryId ※自動入力 | E2: effectId 薬効 ▼日本語で選択 | F2: effectId ※自動入力 | G2: reactionId 調合時効果 ▼日本語で選択 | H2: reactionId ※自動入力 | I2: description 説明文 | J2: メモ、採取後更新されるテキスト | K2: 実装済? ✔を入力
A3: item_001 | B3: ニガタケ | C3: 菌類 | D3: {=IFERROR(INDEX('値リスト'!$A$3:$A$9,MATCH(C3,'値リスト'!$B$3:$B$9,0)),"")} -> fungi | E3: 治癒 | F3: {=IFERROR(INDEX('値リスト'!$A$14:$A$24,MATCH(E3,'値リスト'!$B$14:$B$24,0)),"")} -> healing | G3: 保存 | H3: {=IFERROR(INDEX('値リスト'!$A$27:$A$33,MATCH(G3,'値リスト'!$B$27:$B$33,0)),"")} -> preserve | I3: ありふれたキノコ。薬の材料になる。 | J3: 基本素材 よく生えているキノコ。意外なことに薬になるが、味は良くない。火を加えると薬効が高まるが、味もひどく苦くなる。
A4: item_002 | B4: ハシリタケ | C4: 菌類 | D4: {=IFERROR(INDEX('値リスト'!$A$3:$A$9,MATCH(C4,'値リスト'!$B$3:$B$9,0)),"")} -> fungi | E4: 興奮 | F4: {=IFERROR(INDEX('値リスト'!$A$14:$A$24,MATCH(E4,'値リスト'!$B$14:$B$24,0)),"")} -> stimulation | G4: 浸透 | H4: {=IFERROR(INDEX('値リスト'!$A$27:$A$33,MATCH(G4,'値リスト'!$B$27:$B$33,0)),"")} -> permeate | I4: 夜歩き出すという伝説のあるキノコ | J4: 一晩に数メートルから十数メートル移動するキノコ。いくつかの種類があるが、多量に摂取すると毒となる。少量なら興奮効果をもたらす。
A5: item_003 | B5: ニガハシリダケ | C5: 菌類 | D5: {=IFERROR(INDEX('値リスト'!$A$3:$A$9,MATCH(C5,'値リスト'!$B$3:$B$9,0)),"")} -> fungi | E5: 興奮 | F5: {=IFERROR(INDEX('値リスト'!$A$14:$A$24,MATCH(E5,'値リスト'!$B$14:$B$24,0)),"")} -> stimulation | G5: 揮発 | H5: {=IFERROR(INDEX('値リスト'!$A$27:$A$33,MATCH(G5,'値リスト'!$B$27:$B$33,0)),"")} -> volatile | I5: ニガタケによく似ているが、現れては消えて夜の旅人の道行を惑わすという。 | J5: ニガタケによく似たハシリダケの一種。どこにでも見かけるキノコ、ニガタケに紛れて見つけにくい。ハシリダケの一種であるため、一晩に十メートル前後移動するが、じっと見つめていないとわからないため見つけにくい。キノコを目印にした旅人を惑わす。 とれる場所：森 林 取れる時間帯：夜は確率が上がる。昼はニガタケにまじってまれに取れることがある。 調合のヒント：ニガタケとハシリタケの特性を持つが、鮮度が落ちるのが速い。
A6: item_004 | B6: ドロワリタケ | C6: 菌類 | D6: {=IFERROR(INDEX('値リスト'!$A$3:$A$9,MATCH(C6,'値リスト'!$B$3:$B$9,0)),"")} -> fungi | E6: 滋養強壮 | F6: {=IFERROR(INDEX('値リスト'!$A$14:$A$24,MATCH(E6,'値リスト'!$B$14:$B$24,0)),"")} -> tonic | G6: 触媒 | H6: {=IFERROR(INDEX('値リスト'!$A$27:$A$33,MATCH(G6,'値リスト'!$B$27:$B$33,0)),"")} -> catalyst | I6: 沼地の泥炭層から生える黒くて平たいキノコ。水分を非常に多く含む。 | J6: 泥の中ではその姿を捉えることは叶わないが、採取し洗ってみれば、泥炭の養分を凝縮したような漆黒の弾力が現れる。滋養強壮の薬として名高いが、真に驚くべきはその「触媒」としての力だ。このキノコを釜に投じれば、一夜で成長するその生命力が、本来は反応の遅い重い素材同士を強引に結びつけ、変化の時を早めてくれる。
A7: item_005 | B7: ヌメリヒラタケ | C7: 菌類 | D7: {=IFERROR(INDEX('値リスト'!$A$3:$A$9,MATCH(C7,'値リスト'!$B$3:$B$9,0)),"")} -> fungi | E7: 解毒 | F7: {=IFERROR(INDEX('値リスト'!$A$14:$A$24,MATCH(E7,'値リスト'!$B$14:$B$24,0)),"")} -> detox | G7: 分離 | H7: {=IFERROR(INDEX('値リスト'!$A$27:$A$33,MATCH(G7,'値リスト'!$B$27:$B$33,0)),"")} -> separate | I7: 腐った倒木に群生し、分解力が強い。 | J7: 常に纏っている灰色の粘液は、倒木を分解し尽くす強欲な生命力の表れだ。この粘液は、調合において「分離」の力を発揮する。薬液に含まれる不要な濁りや、素材が持つ雑多な魔力をこの粘液が絡め取り、純粋な成分だけを鮮やかに切り離してくれる。化粧品に使われるのは、その清浄なまでの分解力ゆえだろう。
A8: item_006 | B8: ヤセボソシメジ | C8: 菌類 | D8: {=IFERROR(INDEX('値リスト'!$A$3:$A$9,MATCH(C8,'値リスト'!$B$3:$B$9,0)),"")} -> fungi | E8: 治癒 | F8: {=IFERROR(INDEX('値リスト'!$A$14:$A$24,MATCH(E8,'値リスト'!$B$14:$B$24,0)),"")} -> healing | H8: {=IFERROR(INDEX('値リスト'!$A$27:$A$33,MATCH(G8,'値リスト'!$B$27:$B$33,0)),"")} | I8: 針葉樹の根元にひっそりと生える。見た目に反して旨味が強く、出汁によく出る。 | J8: 針葉樹の影で今にも折れそうな姿をしているが、その身には驚くほどの「溶けやすさ」を秘めている。熱を加えた瞬間、形を失って薬液に溶け込み、周囲の素材の旨味と力を一つに束ね上げる。頑固で混ざり合わない素材同士を繋ぐその様子は、弱々しい見た目に反して、調合釜の中では誰よりも優れた「仲介役」となる。
A9: item_007 | B9: ウロコモドキ | C9: 菌類 | D9: {=IFERROR(INDEX('値リスト'!$A$3:$A$9,MATCH(C9,'値リスト'!$B$3:$B$9,0)),"")} -> fungi | E9: 鎮静 | F9: {=IFERROR(INDEX('値リスト'!$A$14:$A$24,MATCH(E9,'値リスト'!$B$14:$B$24,0)),"")} -> sedation | G9: 凝固 | H9: {=IFERROR(INDEX('値リスト'!$A$27:$A$33,MATCH(G9,'値リスト'!$B$27:$B$33,0)),"")} -> coagulate | I9: 傘の表面が魚の鱗のように硬質化したキノコ。すりつぶすと研磨剤のような粉になる。 | J9: 傘の表面を覆う魚の鱗は、石のように硬く、並の刃では傷一つつかない。しかし、これを根気よくすりつぶして粉末にすれば、液体を瞬時に「凝固」させる強力な固め剤となる。滴るような薬液を、持ち運びやすい丸薬や固形へと変容させる際、このキノコの持つ「守りの硬さ」が役立つのだ。
A10: item_008 | B10: カビツキヌメリ | C10: 菌類 | D10: {=IFERROR(INDEX('値リスト'!$A$3:$A$9,MATCH(C10,'値リスト'!$B$3:$B$9,0)),"")} -> fungi | E10: 猛毒 | F10: {=IFERROR(INDEX('値リスト'!$A$14:$A$24,MATCH(E10,'値リスト'!$B$14:$B$24,0)),"")} -> poison | G10: 触媒 | H10: {=IFERROR(INDEX('値リスト'!$A$27:$A$33,MATCH(G10,'値リスト'!$B$27:$B$33,0)),"")} -> catalyst | I10: 他のキノコに寄生する白い菌。強い「発酵」を促す成分がある。 | J10: 他の菌を侵食し、その性質を根底から書き換えてしまう寄生菌。採取した後は、この白い菌が持つ恐るべき「浸透」の力だけを利用する。一緒に入れた素材の核にある力を強制的に引き出し、ベースとなる水へと移し替えてしまう。その力は、まるで他の素材の魂を水へと溶かし出すかのようだ。
A11: item_009 | B11: スナボコリタケ | C11: 菌類 | D11: {=IFERROR(INDEX('値リスト'!$A$3:$A$9,MATCH(C11,'値リスト'!$B$3:$B$9,0)),"")} -> fungi | F11: {=IFERROR(INDEX('値リスト'!$A$14:$A$24,MATCH(E11,'値リスト'!$B$14:$B$24,0)),"")} | G11: 揮発 | H11: {=IFERROR(INDEX('値リスト'!$A$27:$A$33,MATCH(G11,'値リスト'!$B$27:$B$33,0)),"")} -> volatile | I11: 乾燥した砂地に生える。衝撃を与えると細かい胞子（粉末）を噴き出す。 | J11: 衝撃を与えれば最後、このキノコは一瞬で胞子の煙へと化す。この「揮発」しやすさは、調合においても最大の難所となる。熱を加えすぎれば、丹精込めた薬効もすべて煙となって消えてしまうだろう。薬の力を空気へと逃がさないよう、調合の最後にそっと加える繊細な手捌きが求められる。
A12: item_010 | B12: ベニテングダマシ | C12: 菌類 | D12: {=IFERROR(INDEX('値リスト'!$A$3:$A$9,MATCH(C12,'値リスト'!$B$3:$B$9,0)),"")} -> fungi | E12: 解毒 | F12: {=IFERROR(INDEX('値リスト'!$A$14:$A$24,MATCH(E12,'値リスト'!$B$14:$B$24,0)),"")} -> detox | G12: 中和 | H12: {=IFERROR(INDEX('値リスト'!$A$27:$A$33,MATCH(G12,'値リスト'!$B$27:$B$33,0)),"")} -> neutralize | I12: 毒キノコにそっくりだが毒はない。非常に苦く、「良薬口に苦し」を体現する。 | J12: 猛毒のベニテングタケを模したその姿は、自らを守るための嘘に過ぎない。実際には毒などなく、ただただ閉口するほどに苦い。しかし、その「良薬口に苦し」を地で行く強烈な苦味は、他の素材が持つ尖った毒性を打ち消す「中和」の力を秘めている。偽物が本物を制する、奇妙な調和をもたらすキノコだ。
A13: item_011 | B13: クサリフフダケ | C13: 菌類 | D13: {=IFERROR(INDEX('値リスト'!$A$3:$A$9,MATCH(C13,'値リスト'!$B$3:$B$9,0)),"")} -> fungi | E13: 解毒 | F13: {=IFERROR(INDEX('値リスト'!$A$14:$A$24,MATCH(E13,'値リスト'!$B$14:$B$24,0)),"")} -> detox | H13: {=IFERROR(INDEX('値リスト'!$A$27:$A$33,MATCH(G13,'値リスト'!$B$27:$B$33,0)),"")} | I13: 腐肉の近くに生える独特の臭気を放つキノコ。解毒剤の反転素材として使われる。 | J13: 腐肉の傍らでその臭気を吸って育つこのキノコは、死の際にある素材を好む。通常、毒を消すために使われる素材だが、その本質は「反転」にある。清浄な薬液をあえて腐敗の淵へと追い込み、極限の状態で見せる「毒をもって毒を制する」という危うい解毒の道行へ、調合者を誘う。
A14: item_012 | B14: ネバリイグチ | C14: 菌類 | D14: {=IFERROR(INDEX('値リスト'!$A$3:$A$9,MATCH(C14,'値リスト'!$B$3:$B$9,0)),"")} -> fungi | F14: {=IFERROR(INDEX('値リスト'!$A$14:$A$24,MATCH(E14,'値リスト'!$B$14:$B$24,0)),"")} | G14: 凝固 | H14: {=IFERROR(INDEX('値リスト'!$A$27:$A$33,MATCH(G14,'値リスト'!$B$27:$B$33,0)),"")} -> coagulate | I14: 松林の地中に埋まって生える。掘り起こすと強烈な粘り気があり、接合剤の役割を果たす。 | J14: 地中に隠れたその身を掘り起こせば、糸を引くような強烈な粘り気が手につく。この粘りこそが、バラバラな成分を繋ぎ止める「凝固」の源泉だ。熱を加えてもその粘りは失われず、接合剤として薬を一つにまとめ上げ、完成した薬の形を永く保つための楔となる。
A15: item_013 | B15: シロガネタケ | C15: 菌類 | D15: {=IFERROR(INDEX('値リスト'!$A$3:$A$9,MATCH(C15,'値リスト'!$B$3:$B$9,0)),"")} -> fungi | F15: {=IFERROR(INDEX('値リスト'!$A$14:$A$24,MATCH(E15,'値リスト'!$B$14:$B$24,0)),"")} | G15: 保存 | H15: {=IFERROR(INDEX('値リスト'!$A$27:$A$33,MATCH(G15,'値リスト'!$B$27:$B$33,0)),"")} -> preserve | I15: 高山の岩肌にへばりつく白く乾いたキノコ。極寒に耐える性質（耐冷性）を持つ。 | J15: 高山の凍てつく岩肌で、白く乾いたまま時を止めている。極寒に耐えうるその性質は、採取後も失われない。調合液にこのシロガネタケを加えれば、その「保存」の力が熱による劣化を防ぎ、薬の鮮度を雪の中に閉じ込めたかのように瑞々しく保ってくれる。
A16: item_014 | B16: ホウオウノハネ | C16: 菌類 | D16: {=IFERROR(INDEX('値リスト'!$A$3:$A$9,MATCH(C16,'値リスト'!$B$3:$B$9,0)),"")} -> fungi | E16: 興奮 | F16: {=IFERROR(INDEX('値リスト'!$A$14:$A$24,MATCH(E16,'値リスト'!$B$14:$B$24,0)),"")} -> stimulation | G16: 触媒 | H16: {=IFERROR(INDEX('値リスト'!$A$27:$A$33,MATCH(G16,'値リスト'!$B$27:$B$33,0)),"")} -> catalyst | I16: 深紅と金色のグラデーションを持つ扇状のキノコ。煮出すと燃えるような熱を持つ。 | J16: 煮出すと、まるで鳳凰の羽ばたきのように、釜の中に燃えるような熱が広がる。このキノコ自体が激しい変化を促す「触媒」であり、本来は決して混ざり合うことのない水と油、あるいは対立する属性の素材を、熱の奔流によって強引に融和させてしまう。
B17: ユウヒダケ | C17: 菌類 | E17: 防護 | G17: 触媒 | I17: 夕暮れ時にのみ赤く発光するキノコ。 | J17: 光を蓄える性質があり、乾燥させて粉にすると火を近づけずとも激しく反応する。それ自体が変化の火種となる「触媒」の性質を持ち、本来は混ざり合わない油と水のような素材を強引に反応させる力がある。
A18: item_015 | B18: ミズギワソウ | C18: 植物 | D18: {=IFERROR(INDEX('値リスト'!$A$3:$A$9,MATCH(C18,'値リスト'!$B$3:$B$9,0)),"")} -> flora | E18: 解毒 | F18: {=IFERROR(INDEX('値リスト'!$A$14:$A$24,MATCH(E18,'値リスト'!$B$14:$B$24,0)),"")} -> detox | G18: 分離 | H18: {=IFERROR(INDEX('値リスト'!$A$27:$A$33,MATCH(G18,'値リスト'!$B$27:$B$33,0)),"")} -> separate | I18: 川の合流地点にのみ自生する。茎がストロー状で、不純物を濾過する性質がある。 | J18: 川の合流地点で、二つの異なる水流から魔力を選別して吸収している。ストロー状の茎は「不純な魔力」を濾過する天然のフィルターであり、調合液を通すことで、毒性や雑味だけを鮮やかに「分離」することができる。
A19: item_016 | B19: イバラアザミ | C19: 植物 | D19: {=IFERROR(INDEX('値リスト'!$A$3:$A$9,MATCH(C19,'値リスト'!$B$3:$B$9,0)),"")} -> flora | E19: 治癒 | F19: {=IFERROR(INDEX('値リスト'!$A$14:$A$24,MATCH(E19,'値リスト'!$B$14:$B$24,0)),"")} -> healing | G19: 浸透 | H19: {=IFERROR(INDEX('値リスト'!$A$27:$A$33,MATCH(G19,'値リスト'!$B$27:$B$33,0)),"")} -> permeate | I19: 鋭いトゲを持つ野草。傷をたちどころに治すという伝説がある。 | J19: 鋭いトゲは魔を払う力を持つ。根に蓄えられた瑞々しい液は、生命力の奔流そのもの。切り口から滴る白い液は、傷口に触れると凝固して瞬時に傷を塞ぐ。内臓の傷をも癒やすという伝説は、止血効果によるもの。
A20: item_017 | B20: カサカサ草 | C20: 植物 | D20: {=IFERROR(INDEX('値リスト'!$A$3:$A$9,MATCH(C20,'値リスト'!$B$3:$B$9,0)),"")} -> flora | E20: なし | F20: {=IFERROR(INDEX('値リスト'!$A$14:$A$24,MATCH(E20,'値リスト'!$B$14:$B$24,0)),"")} -> none | G20: 揮発 | H20: {=IFERROR(INDEX('値リスト'!$A$27:$A$33,MATCH(G20,'値リスト'!$B$27:$B$33,0)),"")} -> volatile | I20: 一年中枯れたような茶褐色の葉を持つ。油分を多く含み、火種（着火材）に最適。 | J20: 乾ききった茶褐色の葉には、指で触れるだけで油がにじむ。この油こそが、調合における「揮発」の源泉だ。熱を加えた瞬間、葉は白い煙となって一息に気化し、混ぜ合わせた素材の成分を空気へと引き連れていく。気体薬や燻し薬を作る際の着火剤として、調合者たちが重宝する草だ。
A21: item_018 | B21: オオツユグサ | C21: 植物 | D21: {=IFERROR(INDEX('値リスト'!$A$3:$A$9,MATCH(C21,'値リスト'!$B$3:$B$9,0)),"")} -> flora | E21: 鎮静 | F21: {=IFERROR(INDEX('値リスト'!$A$14:$A$24,MATCH(E21,'値リスト'!$B$14:$B$24,0)),"")} -> sedation | G21: 凝固 | H21: {=IFERROR(INDEX('値リスト'!$A$27:$A$33,MATCH(G21,'値リスト'!$B$27:$B$33,0)),"")} -> coagulate | I21: 早朝、葉の縁に大きな雫を溜める性質がある。水が貴重な場所での水源。 | J21: 夜明け前、葉の縁にぷるりと膨らむ大粒の雫は、一日のうちで最も静謐な時間を閉じ込めている。この雫を集めて薬液に加えれば、昂った成分の動きを宥め、ゆっくりと「凝固」させる穏やかな力を発揮する。荒ぶる素材を落ち着かせ、一つの形にまとめる、夜明けの静けさを纏った草だ。
A22: item_019 | B22: ニガヨモギモドキ | C22: 植物 | D22: {=IFERROR(INDEX('値リスト'!$A$3:$A$9,MATCH(C22,'値リスト'!$B$3:$B$9,0)),"")} -> flora | E22: 治癒 | F22: {=IFERROR(INDEX('値リスト'!$A$14:$A$24,MATCH(E22,'値リスト'!$B$14:$B$24,0)),"")} -> healing | G22: 浸透 | H22: {=IFERROR(INDEX('値リスト'!$A$27:$A$33,MATCH(G22,'値リスト'!$B$27:$B$33,0)),"")} -> permeate | I22: 非常に香りが強く、虫除けに使われる。乾燥させて煎じると腹痛に効く。 | J22: その強烈な香気は、触れるものすべての奥深くへと染み入っていく。煎じれば腹の底まで温もりが「浸透」し、痛みの根を解きほぐす。虫すら寄せ付けぬその気を薬液に宿すことで、塗り薬や吸引薬の効果を皮の奥まで届ける媒介となる。刺激的な香りの裏に、静かで深い癒しの力を持つ草だ。
A23: item_020 | B23: イワノボリツル | C23: 植物 | D23: {=IFERROR(INDEX('値リスト'!$A$3:$A$9,MATCH(C23,'値リスト'!$B$3:$B$9,0)),"")} -> flora | E23: 防護 | F23: {=IFERROR(INDEX('値リスト'!$A$14:$A$24,MATCH(E23,'値リスト'!$B$14:$B$24,0)),"")} -> insulation | G23: 凝固 | H23: {=IFERROR(INDEX('値リスト'!$A$27:$A$33,MATCH(G23,'値リスト'!$B$27:$B$33,0)),"")} -> coagulate | I23: 岩壁を這うように伸びる強靭なツル。繊維が丈夫で、煮出すと丈夫な紐になる。 | J23: 岩の割れ目に爪を立てるようにして這い上がるその繊維は、引いても切れず、曲げても折れない。調合釜に投じれば、ばらばらに漂う成分を繊維で絡め取るように「凝固」させ、頑丈な薬の形を作り上げる。その丈夫さが体を守る「防護」の薬効へと転じ、傷口や患部を外の脅威から遮断する盾となる。
A24: item_021 | B24: ツボミカズラ | C24: 植物 | D24: {=IFERROR(INDEX('値リスト'!$A$3:$A$9,MATCH(C24,'値リスト'!$B$3:$B$9,0)),"")} -> flora | E24: 滋養強壮 | F24: {=IFERROR(INDEX('値リスト'!$A$14:$A$24,MATCH(E24,'値リスト'!$B$14:$B$24,0)),"")} -> tonic | G24: 保存 | H24: {=IFERROR(INDEX('値リスト'!$A$27:$A$33,MATCH(G24,'値リスト'!$B$27:$B$33,0)),"")} -> preserve | I24: 花が開かず、蕾のまま結実する珍しい植物。栄養が凝縮されている。 | J24: 花開くことを拒み、すべての栄養を蕾の中に凝縮させたまま結実する蔓植物。その内に秘められた強烈な生命力は、調合において「保存 」の気質として現れる。完成した薬の中に、この蕾に閉じ込められた「時」を分け与えることで、薬効が腐敗するのを防ぎ、長きにわたってその力を維持させる 。
A25: item_022 | B25: ハッカガヤ | C25: 植物 | D25: {=IFERROR(INDEX('値リスト'!$A$3:$A$9,MATCH(C25,'値リスト'!$B$3:$B$9,0)),"")} -> flora | E25: 治癒 | F25: {=IFERROR(INDEX('値リスト'!$A$14:$A$24,MATCH(E25,'値リスト'!$B$14:$B$24,0)),"")} -> healing | G25: 浸透 | H25: {=IFERROR(INDEX('値リスト'!$A$27:$A$33,MATCH(G25,'値リスト'!$B$27:$B$33,0)),"")} -> permeate | I25: 踏むと爽やかな香りが広がる草原の草。清涼感があり、熱を冷ます効果がある。 | J25: 踏みしめるたびに清涼な香気が立ち上るこの草は、冷たさを肌の奥へと送り込む力を持つ。その香りを薬液に移せば、「浸透」の気質として表れ、熱を帯びた患部の深部まで癒しの冷気を届ける。熱病や炎症を和らげる薬において、効果を体の芯まで届ける道案内の役を担う。
A26: item_023 | B26: ネバリダイコン | C26: 植物 | D26: {=IFERROR(INDEX('値リスト'!$A$3:$A$9,MATCH(C26,'値リスト'!$B$3:$B$9,0)),"")} -> flora | E26: 滋養強壮 | F26: {=IFERROR(INDEX('値リスト'!$A$14:$A$24,MATCH(E26,'値リスト'!$B$14:$B$24,0)),"")} -> tonic | G26: 保存 | H26: {=IFERROR(INDEX('値リスト'!$A$27:$A$33,MATCH(G26,'値リスト'!$B$27:$B$33,0)),"")} -> preserve | I26: 砂地に深く刺さった細長い根。水分を蓄える力が強く、保湿剤の原料になる。 | J26: 砂漠の乾燥に抗い、砂の奥深くに水分を抱えたまま生き延びるこの根は、強靭な生命力の塊だ。調合液に加えれば、その「保存」の力が薬液全体に行き渡り、他の素材が揮発したり腐敗するのを防ぐ。同時に凝縮された滋養が「滋養強壮」として肉体の疲弊を回復させる、砂漠の恵みだ。
A27: item_024 | B27: ミツユキソウ | C27: 植物 | D27: {=IFERROR(INDEX('値リスト'!$A$3:$A$9,MATCH(C27,'値リスト'!$B$3:$B$9,0)),"")} -> flora | E27: 神秘 | F27: {=IFERROR(INDEX('値リスト'!$A$14:$A$24,MATCH(E27,'値リスト'!$B$14:$B$24,0)),"")} -> mystic | G27: 保存 | H27: {=IFERROR(INDEX('値リスト'!$A$27:$A$33,MATCH(G27,'値リスト'!$B$27:$B$33,0)),"")} -> preserve | I27: 雪解けのわずかな期間にのみ姿を現す白い花。 | J27: 雪解けの一瞬だけ顔を出し、また雪の下へと戻っていくこの花は、時間そのものを凝らせたような白さをしている。摘み取った瞬間から時が止まるかのようにその姿を保ち、調合液の中でも「保存」の力として働き、薬の劣化を長く拒む。その稀少な咲き方が宿す不思議な力は、魔力回路を一時的に開く「神秘」の薬効をもたらす。
A28: item_025 | B28: リュウノツノ | C28: 植物 | D28: {=IFERROR(INDEX('値リスト'!$A$3:$A$9,MATCH(C28,'値リスト'!$B$3:$B$9,0)),"")} -> flora | E28: 安定 | F28: {=IFERROR(INDEX('値リスト'!$A$14:$A$24,MATCH(E28,'値リスト'!$B$14:$B$24,0)),"")} -> stable | G28: 凝固 | H28: {=IFERROR(INDEX('値リスト'!$A$27:$A$33,MATCH(G28,'値リスト'!$B$27:$B$33,0)),"")} -> coagulate | I28: 砂漠の岩場に突き出た、ねじれた硬い枝。バラバラな成分を固める性質がある。 | J28: 砂漠の過酷な乾燥に耐え、石のようにねじ曲がったその枝は、バラバラな属性を一つに束ねる「凝固」の力を象徴している。この硬い枝を砕いて投じれば、水に溶け出そうとする不安定な成分を物理的に絡め取り、一つの安定した霊薬へと形を成さしめる。
A29: item_026 | B29: オロチノイバラ | C29: 植物 | D29: {=IFERROR(INDEX('値リスト'!$A$3:$A$9,MATCH(C29,'値リスト'!$B$3:$B$9,0)),"")} -> flora | E29: 猛毒 | F29: {=IFERROR(INDEX('値リスト'!$A$14:$A$24,MATCH(E29,'値リスト'!$B$14:$B$24,0)),"")} -> poison | G29: 分離 | H29: {=IFERROR(INDEX('値リスト'!$A$27:$A$33,MATCH(G29,'値リスト'!$B$27:$B$33,0)),"")} -> separate | I29: 八方にうねるように伸びる猛毒の蔓。硬い素材を溶かして分解するという。 | J29: 八方にのたうつ猛毒の蔓は、獲物を締め上げるのではなく「溶かして喰らう」ためのものだ。調合においても、その破壊的な「分離」の力は健在である。どんなに硬い鉱石であっても、この蔓と共に煮れば成分が解きほぐされ、必要な力だけを抽出することができる。
... A40: item_037 | B40: キリンノナミダ | C40: 鉱物 | D40: {=IFERROR(INDEX('値リスト'!$A$3:$A$9,MATCH(C40,'値リスト'!$B$3:$B$9,0)),"")} -> mineral | E40: 解毒 | F40: {=IFERROR(INDEX('値リスト'!$A$14:$A$24,MATCH(E40,'値リスト'!$B$14:$B$24,0)),"")} -> detox | G40: 中和 | H40: {=IFERROR(INDEX('値リスト'!$A$27:$A$33,MATCH(G40,'値リスト'!$B$27:$B$33,0)),"")} -> neutralize | I40: 虹色の光沢を持つ珍しい樹脂の化石。毒性を打ち消す浄化の性質を持つ。 | J40: 伝説の獣が流した涙が固まったという、虹色の化石。その輝きは、万物の毒性を浄化する至高の「中和」の力を宿している。どれほど危険な素材を組み合わせたとしても、この石を最後に一粒加えるだけで、禍々しい反応は凪ぎ、清らかな聖薬へと生まれ変わる。
A41: item_038 | B41: 鍾乳洞の滴り | C41: 水質 | D41: {=IFERROR(INDEX('値リスト'!$A$3:$A$9,MATCH(C41,'値リスト'!$B$3:$B$9,0)),"")} -> liquid | F41: {=IFERROR(INDEX('値リスト'!$A$14:$A$24,MATCH(E41,'値リスト'!$B$14:$B$24,0)),"")} | G41: 凝固 | H41: {=IFERROR(INDEX('値リスト'!$A$27:$A$33,MATCH(G41,'値リスト'!$B$27:$B$33,0)),"")} -> coagulate | I41: 岩の滴りが集まった水。バラバラな素材を一つに結び安定させる「凝固」の気質を持つ。 | J41: 岩の隙間を幾年もかけて滲み落ちてきた滴は、石の記憶をすべて溶かし込んでいる。この水が薬液に加わると、浮遊する粒子をゆっくりと引き寄せ、ひとつに「凝固」させる。荒ぶる成分を宥め、静かに形を固める。石が時間をかけて鍾乳石を作るように、この水は薬に揺るぎない輪郭を与える。
A42: item_039 | B42: 雨溜まりの泥水 | C42: 水質 | D42: {=IFERROR(INDEX('値リスト'!$A$3:$A$9,MATCH(C42,'値リスト'!$B$3:$B$9,0)),"")} -> liquid | F42: {=IFERROR(INDEX('値リスト'!$A$14:$A$24,MATCH(E42,'値リスト'!$B$14:$B$24,0)),"")} | H42: {=IFERROR(INDEX('値リスト'!$A$27:$A$33,MATCH(G42,'値リスト'!$B$27:$B$33,0)),"")} | I42: 地上の雑多な気が混じった水。素材をわざと腐らせたり発酵を早めたりする際に用いられる。 | J42: 地面に落ちた雨が、土の臭い、草の腐れ、虫の残り香を吸い込んで溜まった水だ。清浄とはほど遠いが、それこそがこの水の本領である。調合釜に加えれば、どんな素材をも緩やかな腐敗へと引き込み、発酵を促す触媒となる。毒も薬も紙一重。この水が腐らせる力こそが、変質の入口だ。
A43: item_040 | B43: 草木の朝露 | C43: 水質 | D43: {=IFERROR(INDEX('値リスト'!$A$3:$A$9,MATCH(C43,'値リスト'!$B$3:$B$9,0)),"")} -> liquid | F43: {=IFERROR(INDEX('値リスト'!$A$14:$A$24,MATCH(E43,'値リスト'!$B$14:$B$24,0)),"")} | G43: 浸透 | H43: {=IFERROR(INDEX('値リスト'!$A$27:$A$33,MATCH(G43,'値リスト'!$B$27:$B$33,0)),"")} -> permeate | I43: 天から降り汚れを知らない清らかな水。草木の繊細な薬効をそのまま吸い出す力を持つ。 | J43: 夜明け前、草木の葉が天の清気を受けて結んだ露。一粒として濁りを知らぬその水は、素材が持つ本来の力を丸ごと「浸透」させて吸い出す。添加物も雑味も混じらず、ただ純粋に薬効だけを引き出す。繊細な花弁や希少な根から力を損なわず引き出したいとき、調合者がまず手に取る水だ。
A44: item_041 | B44: 鉄渋の湧き水 | C44: 水質 | D44: {=IFERROR(INDEX('値リスト'!$A$3:$A$9,MATCH(C44,'値リスト'!$B$3:$B$9,0)),"")} -> liquid | F44: {=IFERROR(INDEX('値リスト'!$A$14:$A$24,MATCH(E44,'値リスト'!$B$14:$B$24,0)),"")} | G44: 保存 | H44: {=IFERROR(INDEX('値リスト'!$A$27:$A$33,MATCH(G44,'値リスト'!$B$27:$B$33,0)),"")} -> preserve | I44: 大地の血が混じったような重く渋い水。色や効能を素材に深く刻み込み定着させる性質がある。 | J44: 大地の鉄分が血のように溶け込んだ重く渋い水。口に含めば、舌に鈍い鉄の味が長く残る。この定着力こそが調合における「保存」の源だ。薬液に加えれば、素材が持つ色と効能を深く刻み込み、完成した薬の力が容易に褪せないよう大地の重さで封じ込める。
A45: item_042 | B45: 雪解けの走り水 | C45: 水質 | D45: {=IFERROR(INDEX('値リスト'!$A$3:$A$9,MATCH(C45,'値リスト'!$B$3:$B$9,0)),"")} -> liquid | F45: {=IFERROR(INDEX('値リスト'!$A$14:$A$24,MATCH(E45,'値リスト'!$B$14:$B$24,0)),"")} | H45: {=IFERROR(INDEX('値リスト'!$A$27:$A$33,MATCH(G45,'値リスト'!$B$27:$B$33,0)),"")} | I45: 冬の眠りから覚めたばかりの勢いのある水。乾燥して眠った素材に一時的な活力を吹き込む。 | J45: 雪が解けて地表を走り始めたばかりの水は、冬の眠りを破った勢いをそのまま宿している。乾燥して力を失いかけた素材に加えれば、その奔流が眠った成分を目覚めさせ、反応をわずかに活性化させる。長くは続かない一時の高揚だが、調合の起点を作る呼び水として侮れない。
A46: item_043 | B46: 古井戸の溜まり水 | C46: 水質 | D46: {=IFERROR(INDEX('値リスト'!$A$3:$A$9,MATCH(C46,'値リスト'!$B$3:$B$9,0)),"")} -> liquid | F46: {=IFERROR(INDEX('値リスト'!$A$14:$A$24,MATCH(E46,'値リスト'!$B$14:$B$24,0)),"")} | G46: 保存 | H46: {=IFERROR(INDEX('値リスト'!$A$27:$A$33,MATCH(G46,'値リスト'!$B$27:$B$33,0)),"")} -> preserve | I46: 光を拒み静寂を湛えた深い水。調合した薬が変質しないようその瞬間の効能を封じ込める。 | J46: 光も届かず、音すら吸い込む古い井戸の底に溜まった水。何も変えず、何も動かさず、ただ静かに在り続けてきた。その静寂が調合における「保存」の力となる。薬液に一滴加えるだけで、時の流れそのものを緩やかにするかのように、完成した薬の効能を長くその瞬間のまま封じ込める。
A47: item_044 | B47: 灰から取った灰汁 | C47: 水質 | D47: {=IFERROR(INDEX('値リスト'!$A$3:$A$9,MATCH(C47,'値リスト'!$B$3:$B$9,0)),"")} -> liquid | F47: {=IFERROR(INDEX('値リスト'!$A$14:$A$24,MATCH(E47,'値リスト'!$B$14:$B$24,0)),"")} | G47: 浸透 | H47: {=IFERROR(INDEX('値リスト'!$A$27:$A$33,MATCH(G47,'値リスト'!$B$27:$B$33,0)),"")} -> permeate | I47: 火の残滓（灰）を通した水。頑固な皮や硬い根の結びつきを解き柔らかく解きほぐす。 | J47: 灰を通して濾された強アルカリの水は、触れるものの結びつきを緩め、硬い皮も頑固な根も柔らかく解きほぐす。この「浸透」の力が調合において真価を発揮する。本来は素材の奥深くへ届かない他の成分を、この灰汁が道を切り拓き、奥底まで染み渡らせる。火の残滓が生む、静かな解放の水だ。
A48: item_045 | B48: 地熱帯の硫黄水 | C48: 水質 | D48: {=IFERROR(INDEX('値リスト'!$A$3:$A$9,MATCH(C48,'値リスト'!$B$3:$B$9,0)),"")} -> liquid | F48: {=IFERROR(INDEX('値リスト'!$A$14:$A$24,MATCH(E48,'値リスト'!$B$14:$B$24,0)),"")} | H48: {=IFERROR(INDEX('値リスト'!$A$27:$A$33,MATCH(G48,'値リスト'!$B$27:$B$33,0)),"")} | I48: 大地の熱を孕んで湧き出す鼻を突く水。火を止めた後も薬の中に温かな熱を留め続ける。 | J48: 硫黄の臭いとともに大地の熱を帯びて湧き出すこの水は、火を止めた後も釜の中に温もりを宿し続ける。その持続する熱が調合において固有の働きをする。他の素材が揮発しないよう抑えながら、薬液全体に均一な熱を長く保ち、仕上がりに芯からの温かさを与える。
A49: item_046 | B49: 樹皮を伝う雨水 | C49: 水質 | D49: {=IFERROR(INDEX('値リスト'!$A$3:$A$9,MATCH(C49,'値リスト'!$B$3:$B$9,0)),"")} -> liquid | F49: {=IFERROR(INDEX('値リスト'!$A$14:$A$24,MATCH(E49,'値リスト'!$B$14:$B$24,0)),"")} | G49: 凝固 | H49: {=IFERROR(INDEX('値リスト'!$A$27:$A$33,MATCH(G49,'値リスト'!$B$27:$B$33,0)),"")} -> coagulate | I49: 森の吐息を吸い込んだわずかに粘りある水。本来混じり合わない粉末同士を繋ぎ合わせる。 | J49: 雨が木の幹を伝い落ちる間に、樹皮の樹脂と苔の湿気を吸い込んだわずかに粘りある水。その粘性が「凝固」の源となる。本来は互いを弾く粉末同士を包み込むように繋ぎ合わせ、ひとつの薬の形へとまとめ上げる。森が雨を受け止めるように、この水は成分を静かに抱きまとめる。
A50: item_047 | B50: 深層の塩水 | C50: 水質 | D50: {=IFERROR(INDEX('値リスト'!$A$3:$A$9,MATCH(C50,'値リスト'!$B$3:$B$9,0)),"")} -> liquid | F50: {=IFERROR(INDEX('値リスト'!$A$14:$A$24,MATCH(E50,'値リスト'!$B$14:$B$24,0)),"")} | G50: 分離 | H50: {=IFERROR(INDEX('値リスト'!$A$27:$A$33,MATCH(G50,'値リスト'!$B$27:$B$33,0)),"")} -> separate | I50: 遥か古の海が地底に閉じ込められたもの。素材の奥底に眠る成分を表へと引きずり出す。 | J50: 太古の海が地殻変動で閉じ込められ、濃縮され続けた塩水。その高い塩分濃度が浸透圧として働き、素材の奥底に眠る成分を強引に表面へと引きずり出す。どれほど不溶性の成分でも、この古い海の引力には抗えない。必要な力だけを抽出したいとき、深層の塩水は最も頼れる「分離」の器だ。
...

Sheet ItemSpawns
A1: ItemSpawns（採取場所・時間帯・確率） ― 1行 ＝ itemId × 場所 × 時間帯
A2: itemId → Items シート参照 | B2: locationId 採取場所のID 例: loc_darkforest | C2: timeSlot 時間帯 ▼日本語で選択 | D2: timeSlot ※自動入力 | E2: spawnRate 出現確率 0.0 〜 1.0 | F2: quantity 採取数 省略可(=1) | G2: condition 追加条件 例: rain / winter | H2: 備考
A3: item_001 | B3: loc_darkforest | C3: 夜 | D3: {=IFERROR(INDEX('値リスト'!$G$16:$G$21,MATCH(C3,'値リスト'!$H$16:$H$21,0)),"")} -> night | E3: 0.7 | F3: 1 | H3: 夜の暗い森で高確率
A4: item_001 | B4: loc_darkforest | C4: 夜明け | D4: {=IFERROR(INDEX('値リスト'!$G$16:$G$21,MATCH(C4,'値リスト'!$H$16:$H$21,0)),"")} -> dawn | E4: 0.3 | F4: 1 | H4: 夜明けはやや低め
A5: item_001 | B5: loc_cave_entrance | C5: 夜 | D5: {=IFERROR(INDEX('値リスト'!$G$16:$G$21,MATCH(C5,'値リスト'!$H$16:$H$21,0)),"")} -> night | E5: 0.4 | F5: 1 | H5: 洞窟入口でも出る
A6: item_002 | B6: loc_meadow | C6: 朝 | D6: {=IFERROR(INDEX('値リスト'!$G$16:$G$21,MATCH(C6,'値リスト'!$H$16:$H$21,0)),"")} -> morning | E6: 0.6 | F6: 1 | H6: 朝の草原
A7: item_002 | B7: loc_meadow | C7: 昼 | D7: {=IFERROR(INDEX('値リスト'!$G$16:$G$21,MATCH(C7,'値リスト'!$H$16:$H$21,0)),"")} -> noon | E7: 0.2 | F7: 1 | G7: rain | H7: 雨天時のみ
A8: item_003 | B8: loc_darkforest | C8: 夜 | D8: {=IFERROR(INDEX('値リスト'!$G$16:$G$21,MATCH(C8,'値リスト'!$H$16:$H$21,0)),"")} -> night | E8: 0.2 | F8: 1 | H8: 交雑種は低確率
D9: {=IFERROR(INDEX('値リスト'!$G$16:$G$21,MATCH(C9,'値リスト'!$H$16:$H$21,0)),"")}
D10: {=IFERROR(INDEX('値リスト'!$G$16:$G$21,MATCH(C10,'値リスト'!$H$16:$H$21,0)),"")}
D11: {=IFERROR(INDEX('値リスト'!$G$16:$G$21,MATCH(C11,'値リスト'!$H$16:$H$21,0)),"")}
D12: {=IFERROR(INDEX('値リスト'!$G$16:$G$21,MATCH(C12,'値リスト'!$H$16:$H$21,0)),"")}
D13: {=IFERROR(INDEX('値リスト'!$G$16:$G$21,MATCH(C13,'値リスト'!$H$16:$H$21,0)),"")}
D14: {=IFERROR(INDEX('値リスト'!$G$16:$G$21,MATCH(C14,'値リスト'!$H$16:$H$21,0)),"")}
D15: {=IFERROR(INDEX('値リスト'!$G$16:$G$21,MATCH(C15,'値リスト'!$H$16:$H$21,0)),"")}
D16: {=IFERROR(INDEX('値リスト'!$G$16:$G$21,MATCH(C16,'値リスト'!$H$16:$H$21,0)),"")}
D17: {=IFERROR(INDEX('値リスト'!$G$16:$G$21,MATCH(C17,'値リスト'!$H$16:$H$21,0)),"")}
D18: {=IFERROR(INDEX('値リスト'!$G$16:$G$21,MATCH(C18,'値リスト'!$H$16:$H$21,0)),"")}
D19: {=IFERROR(INDEX('値リスト'!$G$16:$G$21,MATCH(C19,'値リスト'!$H$16:$H$21,0)),"")}
D20: {=IFERROR(INDEX('値リスト'!$G$16:$G$21,MATCH(C20,'値リスト'!$H$16:$H$21,0)),"")}
... D52: {=IFERROR(INDEX('値リスト'!$G$16:$G$21,MATCH(C52,'値リスト'!$H$16:$H$21,0)),"")}
A53: ※ 同じ itemId が複数の場所・時間帯に出現する場合は行を増やして追加。condition は任意。
D54: {=IFERROR(INDEX('値リスト'!$G$16:$G$21,MATCH(C54,'値リスト'!$H$16:$H$21,0)),"")}
D55: {=IFERROR(INDEX('値リスト'!$G$16:$G$21,MATCH(C55,'値リスト'!$H$16:$H$21,0)),"")}
D56: {=IFERROR(INDEX('値リスト'!$G$16:$G$21,MATCH(C56,'値リスト'!$H$16:$H$21,0)),"")}
D57: {=IFERROR(INDEX('値リスト'!$G$16:$G$21,MATCH(C57,'値リスト'!$H$16:$H$21,0)),"")}
D58: {=IFERROR(INDEX('値リスト'!$G$16:$G$21,MATCH(C58,'値リスト'!$H$16:$H$21,0)),"")}
D59: {=IFERROR(INDEX('値リスト'!$G$16:$G$21,MATCH(C59,'値リスト'!$H$16:$H$21,0)),"")}
D60: {=IFERROR(INDEX('値リスト'!$G$16:$G$21,MATCH(C60,'値リスト'!$H$16:$H$21,0)),"")}
D61: {=IFERROR(INDEX('値リスト'!$G$16:$G$21,MATCH(C61,'値リスト'!$H$16:$H$21,0)),"")}
D62: {=IFERROR(INDEX('値リスト'!$G$16:$G$21,MATCH(C62,'値リスト'!$H$16:$H$21,0)),"")}
D63: {=IFERROR(INDEX('値リスト'!$G$16:$G$21,MATCH(C63,'値リスト'!$H$16:$H$21,0)),"")}
D64: {=IFERROR(INDEX('値リスト'!$G$16:$G$21,MATCH(C64,'値リスト'!$H$16:$H$21,0)),"")}
D65: {=IFERROR(INDEX('値リスト'!$G$16:$G$21,MATCH(C65,'値リスト'!$H$16:$H$21,0)),"")}
... D200: {=IFERROR(INDEX('値リスト'!$G$16:$G$21,MATCH(C200,'値リスト'!$H$16:$H$21,0)),"")}

Sheet Recipes
A1: Recipes（data_recipes.js） ― 1行 ＝ 1素材条件 同じ result を複数行で列挙
A2: result 生成物名 （複数行に同名OK） | B2: No 素材 番号 | C2: checkType 判定タイプ ▼日本語で選択 | D2: checkType ※自動入力 | E2: value 判定値 IDまたは値を入力 | F2: processId 加工法 ▼日本語で選択 | G2: processId ※自動入力 | H2: quantity 必要数 省略可(=1) | I2: 備考 代替・バランスメモ | J2: 実装済? ✔を入力
A3: 加速の秘薬 | B3: 1 | C3: 特定アイテムID | D3: {=IFERROR(INDEX('値リスト'!$G$24:$G$28,MATCH(C3,'値リスト'!$H$24:$H$28,0)),"")} -> itemId | E3: item_003 | F3: すりつぶす | G3: {=IFERROR(INDEX('値リスト'!$G$3:$G$11,MATCH(F3,'値リスト'!$H$3:$H$11,0)),"")} -> grind | H3: 1 | I3: ニガハシリダケ限定 | J3: ✔
A4: 加速の秘薬 | B4: 2 | C4: カテゴリID | D4: {=IFERROR(INDEX('値リスト'!$G$24:$G$28,MATCH(C4,'値リスト'!$H$24:$H$28,0)),"")} -> categoryId | E4: liquid | F4: 煮る | G4: {=IFERROR(INDEX('値リスト'!$G$3:$G$11,MATCH(F4,'値リスト'!$H$3:$H$11,0)),"")} -> boil | H4: 1 | I4: 水系ならなんでもOK | J4: ✔
A5: 汎用毒消し | B5: 1 | C5: 薬効ID | D5: {=IFERROR(INDEX('値リスト'!$G$24:$G$28,MATCH(C5,'値リスト'!$H$24:$H$28,0)),"")} -> effectId | E5: detox | F5: 煮る | G5: {=IFERROR(INDEX('値リスト'!$G$3:$G$11,MATCH(F5,'値リスト'!$H$3:$H$11,0)),"")} -> boil | H5: 1 | I5: 解毒効果を持つ素材 | J5: ✔
A6: 汎用毒消し | B6: 2 | C6: 調合時効果ID | D6: {=IFERROR(INDEX('値リスト'!$G$24:$G$28,MATCH(C6,'値リスト'!$H$24:$H$28,0)),"")} -> reactionId | E6: neutralize | F6: そのまま | G6: {=IFERROR(INDEX('値リスト'!$G$3:$G$11,MATCH(F6,'値リスト'!$H$3:$H$11,0)),"")} -> raw | H6: 1 | I6: 中和の性質を持つ素材 | J6: ✔
A7: 蒸留水 | B7: 1 | C7: カテゴリID | D7: categoryId | E7: liquid | F7: 蒸留 | G7: distill | H7: 1 | I7: 水質素材ならなんでもOK
A9: 純化水 | B9: 1 | C9: 特定アイテムID | D9: itemId | E9: 蒸留水 | F9: そのまま | G9: raw | H9: 1 | I9: ベース：蒸留水
A10: 純化水 | B10: 2 | C10: 調合時効果ID | D10: reactionId | E10: separate | F10: 溶かす | G10: dissolve | H10: 1 | I10: 分離特性の素材を溶かす（例：深層の塩水・白砂晶・墨痕石）
A12: 超純水 | B12: 1 | C12: 特定アイテムID | D12: itemId | E12: 蒸留水 | F12: 蒸留 | G12: distill | H12: 1 | I12: 蒸留水をベースに蒸留
A13: 超純水 | B13: 2 | C13: 特定アイテムID | D13: itemId | E13: 純化水 | F13: そのまま | G13: raw | H13: 1 | I13: 純化水を加えて二重浄化
A15: 凝固薬 | B15: 1 | C15: カテゴリID | D15: categoryId | E15: liquid | F15: 煮る | G15: boil | H15: 1 | I15: 水質ベース
A16: 凝固薬 | B16: 2 | C16: 調合時効果ID | D16: reactionId | E16: coagulate | F16: そのまま | G16: raw | H16: 1 | I16: 凝固特性の素材を加える（例：鍾乳洞の滴り・樹皮を伝う雨水）
A18: 浸透溶媒 | B18: 1 | C18: 調合時効果ID | D18: reactionId | E18: permeate | F18: 蒸留 | G18: distill | H18: 1 | I18: 浸透特性の水質を蒸留（例：草木の朝露・灰から取った灰汁）
A19: 浸透溶媒 | B19: 2 | C19: カテゴリID | D19: categoryId | E19: flora | F19: 溶かす | G19: dissolve | H19: 1 | I19: 植物素材を溶かし込む
A21: 強発酵液 | B21: 1 | C21: 特定アイテムID | D21: itemId | E21: item_039 | F21: 発酵させる | G21: ferment | H21: 1 | I21: 雨溜まりの泥水を発酵
A22: 強発酵液 | B22: 2 | C22: カテゴリID | D22: categoryId | E22: fungi | F22: そのまま | G22: raw | H22: 1 | I22: 菌類を加えて発酵を促進
A24: 保存溶液 | B24: 1 | C24: 調合時効果ID | D24: reactionId | E24: preserve | F24: 煮る | G24: boil | H24: 1 | I24: 保存特性の水質を煮る（例：鉄渋の湧き水・古井戸の溜まり水）
A25: 保存溶液 | B25: 2 | C25: カテゴリID | D25: categoryId | E25: mineral | F25: 溶かす | G25: dissolve | H25: 1 | I25: 鉱物素材を溶かし安定性を高める
D26: {=IFERROR(INDEX('値リスト'!$G$24:$G$28,MATCH(C26,'値リスト'!$H$24:$H$28,0)),"")} | G26: {=IFERROR(INDEX('値リスト'!$G$3:$G$11,MATCH(F26,'値リスト'!$H$3:$H$11,0)),"")}
D27: {=IFERROR(INDEX('値リスト'!$G$24:$G$28,MATCH(C27,'値リスト'!$H$24:$H$28,0)),"")} | G27: {=IFERROR(INDEX('値リスト'!$G$3:$G$11,MATCH(F27,'値リスト'!$H$3:$H$11,0)),"")}
D28: {=IFERROR(INDEX('値リスト'!$G$24:$G$28,MATCH(C28,'値リスト'!$H$24:$H$28,0)),"")} | G28: {=IFERROR(INDEX('値リスト'!$G$3:$G$11,MATCH(F28,'値リスト'!$H$3:$H$11,0)),"")}
D29: {=IFERROR(INDEX('値リスト'!$G$24:$G$28,MATCH(C29,'値リスト'!$H$24:$H$28,0)),"")} | G29: {=IFERROR(INDEX('値リスト'!$G$3:$G$11,MATCH(F29,'値リスト'!$H$3:$H$11,0)),"")}
D30: {=IFERROR(INDEX('値リスト'!$G$24:$G$28,MATCH(C30,'値リスト'!$H$24:$H$28,0)),"")} | G30: {=IFERROR(INDEX('値リスト'!$G$3:$G$11,MATCH(F30,'値リスト'!$H$3:$H$11,0)),"")}
D31: {=IFERROR(INDEX('値リスト'!$G$24:$G$28,MATCH(C31,'値リスト'!$H$24:$H$28,0)),"")} | G31: {=IFERROR(INDEX('値リスト'!$G$3:$G$11,MATCH(F31,'値リスト'!$H$3:$H$11,0)),"")}
D32: {=IFERROR(INDEX('値リスト'!$G$24:$G$28,MATCH(C32,'値リスト'!$H$24:$H$28,0)),"")} | G32: {=IFERROR(INDEX('値リスト'!$G$3:$G$11,MATCH(F32,'値リスト'!$H$3:$H$11,0)),"")}
D33: {=IFERROR(INDEX('値リスト'!$G$24:$G$28,MATCH(C33,'値リスト'!$H$24:$H$28,0)),"")} | G33: {=IFERROR(INDEX('値リスト'!$G$3:$G$11,MATCH(F33,'値リスト'!$H$3:$H$11,0)),"")}
D34: {=IFERROR(INDEX('値リスト'!$G$24:$G$28,MATCH(C34,'値リスト'!$H$24:$H$28,0)),"")} | G34: {=IFERROR(INDEX('値リスト'!$G$3:$G$11,MATCH(F34,'値リスト'!$H$3:$H$11,0)),"")}
D35: {=IFERROR(INDEX('値リスト'!$G$24:$G$28,MATCH(C35,'値リスト'!$H$24:$H$28,0)),"")} | G35: {=IFERROR(INDEX('値リスト'!$G$3:$G$11,MATCH(F35,'値リスト'!$H$3:$H$11,0)),"")}
D36: {=IFERROR(INDEX('値リスト'!$G$24:$G$28,MATCH(C36,'値リスト'!$H$24:$H$28,0)),"")} | G36: {=IFERROR(INDEX('値リスト'!$G$3:$G$11,MATCH(F36,'値リスト'!$H$3:$H$11,0)),"")}
D37: {=IFERROR(INDEX('値リスト'!$G$24:$G$28,MATCH(C37,'値リスト'!$H$24:$H$28,0)),"")} | G37: {=IFERROR(INDEX('値リスト'!$G$3:$G$11,MATCH(F37,'値リスト'!$H$3:$H$11,0)),"")}
... D52: {=IFERROR(INDEX('値リスト'!$G$24:$G$28,MATCH(C52,'値リスト'!$H$24:$H$28,0)),"")} | G52: {=IFERROR(INDEX('値リスト'!$G$3:$G$11,MATCH(F52,'値リスト'!$H$3:$H$11,0)),"")}
A53: ※ 同じ result の行をまとめてJS変換。checkType に応じて value に適切なIDを入力（値リストシート参照）。
D54: {=IFERROR(INDEX('値リスト'!$G$24:$G$28,MATCH(C54,'値リスト'!$H$24:$H$28,0)),"")} | G54: {=IFERROR(INDEX('値リスト'!$G$3:$G$11,MATCH(F54,'値リスト'!$H$3:$H$11,0)),"")}
D55: {=IFERROR(INDEX('値リスト'!$G$24:$G$28,MATCH(C55,'値リスト'!$H$24:$H$28,0)),"")} | G55: {=IFERROR(INDEX('値リスト'!$G$3:$G$11,MATCH(F55,'値リスト'!$H$3:$H$11,0)),"")}
D56: {=IFERROR(INDEX('値リスト'!$G$24:$G$28,MATCH(C56,'値リスト'!$H$24:$H$28,0)),"")} | G56: {=IFERROR(INDEX('値リスト'!$G$3:$G$11,MATCH(F56,'値リスト'!$H$3:$H$11,0)),"")}
D57: {=IFERROR(INDEX('値リスト'!$G$24:$G$28,MATCH(C57,'値リスト'!$H$24:$H$28,0)),"")} | G57: {=IFERROR(INDEX('値リスト'!$G$3:$G$11,MATCH(F57,'値リスト'!$H$3:$H$11,0)),"")}
D58: {=IFERROR(INDEX('値リスト'!$G$24:$G$28,MATCH(C58,'値リスト'!$H$24:$H$28,0)),"")} | G58: {=IFERROR(INDEX('値リスト'!$G$3:$G$11,MATCH(F58,'値リスト'!$H$3:$H$11,0)),"")}
D59: {=IFERROR(INDEX('値リスト'!$G$24:$G$28,MATCH(C59,'値リスト'!$H$24:$H$28,0)),"")} | G59: {=IFERROR(INDEX('値リスト'!$G$3:$G$11,MATCH(F59,'値リスト'!$H$3:$H$11,0)),"")}
D60: {=IFERROR(INDEX('値リスト'!$G$24:$G$28,MATCH(C60,'値リスト'!$H$24:$H$28,0)),"")} | G60: {=IFERROR(INDEX('値リスト'!$G$3:$G$11,MATCH(F60,'値リスト'!$H$3:$H$11,0)),"")}
...
